Workbook

Sheet Cover
A1: BRAND LLC: 5 Year Financial Model
A2: US launch of hybrid active optical HDMI cables on Amazon, then eBay and Walmart, B2B installers, a DTC site, Amazon Canada and a pro line
A3: Build date: October 8, 2026. Workbook: output/03_Financial_Model_5Y.xlsx. Generator: build/build_model.py.
A5: How to use
A6: 1. Change the three selectors on the Assumptions tab: Scenario (1 Low, 2 Medium, 3 High), DutyScenario (1 Copper, 2 Fiber, 3 Stress), FXRate (KRW per USD).
A7: 2. Every other tab reads the Active column on Assumptions, so one selector drives every sheet. The Scenario Summary tab shows all three scenarios side by side without changing the selector.
A8: 3. Edit yellow cells only. Black cells are formulas. Green cells are links to another sheet.
A9: 4. Months are model months: Month 1 is the first month with inventory live on Amazon (assumed early 2027). Year 1 is Months 1 to 12.
A10: 5. Months 1 to 18 reproduce the August 2026 Amazon model. Year 2 drivers (ocean freight, fixed cost step up, compliance, FBA fee inflation) start in Month 19.
A11: 6. Recalculate after edits (Excel does this automatically). The build script recalculates with LibreOffice and checks that there are no formula errors.
A13: Legend
A14: Input: yellow fill with blue text
... A19: Tabs in order
A20: Cover | B20: this page
A21: Assumptions | B21: Low, Medium, High side by side, the Active column and the three selectors
A22: FX | B22: KRW per USD input, the three FX scenarios, conversions of capital, the August deal and profit repatriation
A23: SKU Unit Economics | B23: per SKU cost build (FOB, freight, duty by scenario, fees, FBA, referral, ads, returns, net) and the three cost bases
A24: Landed Cost & Tariff Scenarios | B24: duty table, landed COGS % build for the active scenario, waterfall data
A25: Monthly PL Y1 Y2 | B25: Months 1 to 24, Amazon US plus the Year 2 channels, 18 month block
A26: Annual PL Y1 to Y5 | B26: Years 1 to 5 by channel with the check rows to the monthly tab
A27: Cash Flow and Working Capital | B27: inventory purchases, in transit stock, payout lag, cash balance, peak need, runway, funding gap
A28: Funding and Breakeven | B28: funding plan, Day 90 and Month 12 gates with PASS, REVIEW or KILL, Plan B summary
A29: Sensitivity | B29: one way sensitivity of 18 month net and Year 5 net, tornado data
A30: KPI Dashboard | B30: KPI table and the five charts
A31: Levers | B31: the twelve levers mapped to the assumption each one moves
... A33: Plan B | B33: B2B installer distribution plus continued Korea wholesale if Amazon fails
A35: Basis tags: Evidence based = brief section 1, the August deal, the August model or a verified regulatory fact. Management estimate = everything else.
A36: Largest unverified assumption: the factory cost. At the Alibaba benchmark FOB ($17 to $22) the hero SKU loses money at $44.99. See SKU Unit Economics.

Sheet Assumptions
A1: Assumptions
A2: Low, Medium and High side by side. The Active column (F) is what every other sheet reads. Edit yellow cells only.
A3: Scenario selector (1 Low, 2 Medium, 3 High) | C3: 2 | D3: =CHOOSE(Scenario,"Low","Medium","High") -> Medium | E3: active scenario name
A4: Duty scenario selector (1 Copper, 2 Fiber, 3 Stress) | C4: 1 | D4: =CHOOSE(DutyScenario,"Copper","Fiber","Stress") -> Copper | E4: active duty scenario name
A5: FX rate, KRW per USD (scenarios 1,300 / 1,430 / 1,550) | C5: 1430 | D5: ="FX "&TEXT(FXRate,"#,##0")&" KRW per USD" -> FX 1,430 KRW per USD
A7: Driver | B7: Unit | C7: Low | D7: Medium | E7: High | F7: Active | G7: Basis | H7: Note
A9: Eighteen month block (August 2026 Amazon model; Months 1 to 18 reproduce it)
A10: ASP Years 1 and 2 | B10: $ | C10: 38 | D10: 42 | E10: 43 | F10: =INDEX($C10:$E10,1,Scenario) -> 42 | G10: Evidence based | H10: August model Medium $42; Low and High calibrated per spec 2.3
A11: Landed COGS % of revenue, base (copper duty, air then ocean) | B11: % | C11: 0.43 | D11: 0.38 | E11: 0.32 | F11: =INDEX($C11:$E11,1,Scenario) -> 0.38 | G11: Evidence based | H11: August model 38% pending the customs ruling; Low 43%; High 32% assumes fiber ruling, ocean and volume pricing
A12: Returns % Year 1 | B12: % | C12: 0.04 | D12: 0.03 | E12: 0.025 | F12: =INDEX($C12:$E12,1,Scenario) -> 0.03 | G12: Evidence based | H12: August model 3%
A13: Ad spend % Months 1 to 3 | B13: % | C13: 0.37 | D13: 0.3 | E13: 0.26 | F13: =INDEX($C13:$E13,1,Scenario) -> 0.3 | G13: Evidence based | H13: August model 30%; Low plus 7 points; High minus 4 points
A14: Ad spend % Months 4 to 6 | B14: % | C14: 0.29 | D14: 0.22 | E14: 0.18 | F14: =INDEX($C14:$E14,1,Scenario) -> 0.22 | G14: Evidence based
A15: Ad spend % Months 7 to 12 | B15: % | C15: 0.22 | D15: 0.15 | E15: 0.11 | F15: =INDEX($C15:$E15,1,Scenario) -> 0.15 | G15: Evidence based
A16: Ad spend % Months 13 to 18 | B16: % | C16: 0.18 | D16: 0.11 | E16: 0.08 | F16: =INDEX($C16:$E16,1,Scenario) -> 0.11 | G16: Evidence based | H16: August model 11% for Months 13 to 18; Low plus 7 points; High minus 3 points (the 8% floor)
A17: Fixed costs per month Year 1 (software, insurance, misc), Months 1 to 18 | B17: $ | C17: 850 | D17: 850 | E17: 850 | F17: =INDEX($C17:$E17,1,Scenario) -> 850 | G17: Evidence based | H17: August model
A18: Unit ramp multiplier on the Medium ramp, Months 1 to 18 | B18: x | C18: 0.6 | D18: 1 | E18: 1.55 | F18: =INDEX($C18:$E18,1,Scenario) -> 1 | G18: Management estimate | H18: Low 0.60 and High 1.55 per the build spec; Medium ramp is the August deck
A19: Amazon referral fee % | B19: % | C19: 0.15 | D19: 0.15 | E19: 0.15 | F19: =INDEX($C19:$E19,1,Scenario) -> 0.15 | G19: Evidence based | H19: August model; same in every scenario
A20: FBA fulfillment fee per unit, Year 1 (hero basis) | B20: $ | C20: 5.5 | D20: 5.5 | E20: 5.5 | F20: =INDEX($C20:$E20,1,Scenario) -> 5.5 | G20: Evidence based | H20: August model; same in every scenario
A21: Storage and inbound % of revenue | B21: % | C21: 0.02 | D21: 0.02 | E21: 0.02 | F21: =INDEX($C21:$E21,1,Scenario) -> 0.02 | G21: Evidence based | H21: August model; same in every scenario
A22: Professional seller fee per month | B22: $ | C22: 39.99 | D22: 39.99 | E22: 39.99 | F22: =INDEX($C22:$E22,1,Scenario) -> 39.99 | G22: Evidence based | H22: August model; same in every scenario
A23: One time launch costs in Month 1 | B23: $ | C23: 9500 | D23: 9500 | E23: 9500 | F23: =INDEX($C23:$E23,1,Scenario) -> 9500 | G23: Evidence based | H23: August model; same in every scenario
A25: Year 2 to Year 5 drivers (Year 2 changes start in Month 19, after the August horizon)
A26: Year 2 driver start month (ocean landed cost, fixed cost step up, compliance, FBA fee inflation, Year 2 returns and the Months 19 to 24 ad rate begin here) | B26: month | C26: 19 | D26: 19 | E26: 19 | F26: =INDEX($C26:$E26,1,Scenario) -> 19 | G26: Evidence based | H26: Month 19 is the first month after the August 18 month horizon; the compliance charge is spread over the months from here to Month 24
A27: Ad spend % Months 19 to 24 | B27: % | C27: 0.18 | D27: 0.11 | E27: 0.095 | F27: =INDEX($C27:$E27,1,Scenario) -> 0.11 | G27: Management estimate | H27: Low and Medium carry the Months 13 to 18 rate; High steps to its Year 3 rate so the Year 2 ad spend across all channels stays above the 8% floor (8.1% blended; at 8% Amazon only it diluted to 7.4%)
A28: Months 19 to 24 units added per month on top of Month 18 | B28: units | C28: 0 | D28: 100 | E28: 160 | F28: =INDEX($C28:$E28,1,Scenario) -> 100 | G28: Management estimate | H28: Low flat at Month 18
A29: Lost quarter factor (listing suppression or account health event) | B29: x | C29: 0.1 | D29: 1 | E29: 1 | F29: =INDEX($C29:$E29,1,Scenario) -> 1 | G29: Management estimate | H29: Low case only: units at 10% of trend for three months
A30: Lost quarter start month (three months) | B30: month | C30: 19 | D30: 99 | E30: 99 | F30: =INDEX($C30:$E30,1,Scenario) -> 99 | G30: Management estimate | H30: Spec 2.5 said Months 15 to 17; moved to Months 19 to 21 so the Low 18 month block reproduces the August Low case, per the brief
A31: Returns % Year 2 onward (from Month 19) | B31: % | C31: 0.04 | D31: 0.025 | E31: 0.02 | F31: =INDEX($C31:$E31,1,Scenario) -> 0.025 | G31: Management estimate | H31: never below 2%
A32: FBA fee inflation per year from Year 2 | B32: % | C32: 0.03 | D32: 0.03 | E32: 0.03 | F32: =INDEX($C32:$E32,1,Scenario) -> 0.03 | G32: Management estimate
A33: Landed COGS % change vs base, Year 2 (from Month 19) | B33: pts | C33: 0 | D33: -0.015 | E33: -0.01 | F33: =INDEX($C33:$E33,1,Scenario) -> -0.015 | G33: Management estimate | H33: ocean freight and volume
A34: Landed COGS % change vs base, Year 3 | B34: pts | C34: 0 | D34: -0.015 | E34: -0.015 | F34: =INDEX($C34:$E34,1,Scenario) -> -0.015 | G34: Management estimate | H34: spec starting value Medium minus 2.5; held at the Year 2 benefit
A35: Landed COGS % change vs base, Year 4 | B35: pts | C35: 0 | D35: -0.01 | E35: -0.01 | F35: =INDEX($C35:$E35,1,Scenario) -> -0.01 | G35: Management estimate | H35: spec starting value Medium minus 2.0; creep back starts in Year 4 so the Medium net margin compresses at least 1 point from Year 3 to Year 4
A36: Landed COGS % change vs base, Year 5 | B36: pts | C36: 0 | D36: -0.005 | E36: 0 | F36: =INDEX($C36:$E36,1,Scenario) -> -0.005 | G36: Management estimate | H36: creep back toward base (factory price increases, freight volatility); spec starting values minus 1.5 and minus 0.5
A37: Amazon US unit growth Year 3 | B37: % | C37: 0.1 | D37: 0.3 | E37: 0.35 | F37: =INDEX($C37:$E37,1,Scenario) -> 0.3 | G37: Management estimate | H37: spec starting values Low 5, Medium 30, High 35; Low raised 5 points (within the ±5 bound) so Year 5 lands in the 0.7 to 1.2M band
A38: Amazon US unit growth Year 4 | B38: % | C38: 0.08 | D38: 0.2 | E38: 0.25 | F38: =INDEX($C38:$E38,1,Scenario) -> 0.2 | G38: Management estimate | H38: Low raised 5 points within bound
A39: Amazon US unit growth Year 5 | B39: % | C39: 0.05 | D39: 0.12 | E39: 0.15 | F39: =INDEX($C39:$E39,1,Scenario) -> 0.12 | G39: Management estimate | H39: Low raised 5 points within bound
A40: ASP change per year from Year 3 (price competition) | B40: % | C40: -0.04 | D40: -0.04 | E40: -0.03 | F40: =INDEX($C40:$E40,1,Scenario) -> -0.04 | G40: Management estimate | H40: spec starting values minus 3, minus 2, minus 1.5 per year; deepened so contribution margin falls at least 1 point a year overall and Year 5 net lands in band
A41: Roadmap SKU mix uplift to ASP in Year 3 (HDMI 2.2 16K, DP 2.1, USB4 AOC) | B41: % | C41: 0 | D41: 0.03 | E41: 0.03 | F41: =INDEX($C41:$E41,1,Scenario) -> 0.03 | G41: Management estimate | H41: Low has no capital for roadmap SKUs
A42: Ad spend % Year 3 | B42: % | C42: 0.13 | D42: 0.115 | E42: 0.095 | F42: =INDEX($C42:$E42,1,Scenario) -> 0.115 | G42: Management estimate | H42: spec starting values 12, 9.5, 9.0; raised so competition compresses margin at least 1 point a year; never below 8%
A43: Ad spend % Year 4 | B43: % | C43: 0.135 | D43: 0.115 | E43: 0.095 | F43: =INDEX($C43:$E43,1,Scenario) -> 0.115 | G43: Management estimate | H43: spec starting values 12, 9.0, 8.5; see Year 3 note
...

Sheet FX
A1: FX
A2: The only verified cost data is in KRW (August deal). FX moves landed COGS % through the hero FOB share. A USD factory quote removes this effect.
A4: Active FX rate, KRW per USD (input on Assumptions) | B4: =FXRate -> 1430
A6: Item | B6: Active | C6: Scenario 1,300 | D6: Scenario 1,430 | E6: Scenario 1,550 | F6: Basis
A7: FX rate, KRW per USD | B7: =FXRate -> 1430 | C7: 1300 | D7: 1430 | E7: 1550 | F7: Evidence based default 1,430; scenarios per the brief
A8: August 2026 deal totals (inputs from inputs/august_deal_totals.csv; H2 Company to Dioptek, 1,400 units)
A9: August deal units | B9: 1400 | F9: Evidence based: August 2026 deal (inputs/august_deal_totals.csv)
A10: August deal cost, KRW | B10: 19460000 | F10: Evidence based: August 2026 deal (inputs/august_deal_totals.csv)
A11: August deal revenue ex VAT, KRW | B11: 24400000 | F11: Evidence based: August 2026 deal (inputs/august_deal_totals.csv)
A12: August deal gross profit, KRW | B12: 4940000 | F12: Evidence based: August 2026 deal (inputs/august_deal_totals.csv)
A13: August deal gross margin (gross profit divided by revenue) | B13: =B12/B11 -> 0.20245902 | F13: 20.3% in the brief
A15: Conversions at the active FX rate and the three FX scenarios
A16: Hero FOB USD (8K 10M, KRW 11,470 times the FOB factor) | B16: ='SKU Unit Economics'!$D$6/B$7*'SKU Unit Economics'!$B$18 -> 7.3793007 | C16: ='SKU Unit Economics'!$D$6/C$7*'SKU Unit Economics'!$B$18 -> 8.1172308 | D16: ='SKU Unit Economics'!$D$6/D$7*'SKU Unit Economics'!$B$18 -> 7.3793007 | E16: ='SKU Unit Economics'!$D$6/E$7*'SKU Unit Economics'!$B$18 -> 6.808 | F16: Evidence based KRW cost
A17: Landed COGS % delta vs the 1,430 cost base (hero FOB share times (1,430 / FX minus 1)) | B17: =HeroFobShare*(Assumptions!$F$111/B$7-1) -> 0 | C17: =HeroFobShare*(Assumptions!$F$111/C$7-1) -> 0.016402091 | D17: =HeroFobShare*(Assumptions!$F$111/D$7-1) -> 0 | E17: =HeroFobShare*(Assumptions!$F$111/E$7-1) -> -0.012698393 | F17: Model formula
A18: Opening capital $39,000 in KRW | B18: =Assumptions!$F$106*B$7 -> 55770000 | C18: =Assumptions!$F$106*C$7 -> 50700000 | D18: =Assumptions!$F$106*D$7 -> 55770000 | E18: =Assumptions!$F$106*E$7 -> 60450000 | F18: DECISIONS.md
A19: August deal cost in USD | B19: =$B$10/B$7 -> 13608.392 | C19: =$B$10/C$7 -> 14969.231 | D19: =$B$10/D$7 -> 13608.392 | E19: =$B$10/E$7 -> 12554.839 | F19: August deal (input above)
A20: August deal revenue ex VAT in USD | B20: =$B$11/B$7 -> 17062.937 | C20: =$B$11/C$7 -> 18769.231 | D20: =$B$11/D$7 -> 17062.937 | E20: =$B$11/E$7 -> 15741.935 | F20: August deal (input above)
A21: August deal gross profit in USD | B21: =$B$12/B$7 -> 3454.5455 | C21: =$B$12/C$7 -> 3800 | D21: =$B$12/D$7 -> 3454.5455 | E21: =$B$12/E$7 -> 3187.0968 | F21: August deal (input above; about $3,500 at 1,430)
A22: Hero H2 cost KRW 11,470 in USD (Korea landed) | B22: ='SKU Unit Economics'!$D$6/B$7 -> 8.020979 | C22: ='SKU Unit Economics'!$D$6/C$7 -> 8.8230769 | D22: ='SKU Unit Economics'!$D$6/D$7 -> 8.020979 | E22: ='SKU Unit Economics'!$D$6/E$7 -> 7.4 | F22: August deal
A23: Profit repatriation examples (active scenario)
A24: Year 1 net (active scenario) in KRW | B24: ='Annual PL Y1 to Y5'!$C$80*B$7 -> 54397372 | C24: ='Annual PL Y1 to Y5'!$C$80*C$7 -> 49452156 | D24: ='Annual PL Y1 to Y5'!$C$80*D$7 -> 54397372 | E24: ='Annual PL Y1 to Y5'!$C$80*E$7 -> 58962186 | F24: Model
A25: Year 5 net (active scenario) in KRW | B25: ='Annual PL Y1 to Y5'!$G$80*B$7 -> 8.7618183e+08 | C25: ='Annual PL Y1 to Y5'!$G$80*C$7 -> 7.9652894e+08 | D25: ='Annual PL Y1 to Y5'!$G$80*D$7 -> 8.7618183e+08 | E25: ='Annual PL Y1 to Y5'!$G$80*E$7 -> 9.4970758e+08 | F25: Model
A26: Cumulative 5 year net (active scenario) in KRW | B26: ='Annual PL Y1 to Y5'!$G$82*B$7 -> 2.7666569e+09 | C26: ='Annual PL Y1 to Y5'!$G$82*C$7 -> 2.5151427e+09 | D26: ='Annual PL Y1 to Y5'!$G$82*D$7 -> 2.7666569e+09 | E26: ='Annual PL Y1 to Y5'!$G$82*E$7 -> 2.9988239e+09 | F26: Model; before US and Korean tax
A27: Korean overseas financial account report threshold: KRW 500M month end aggregate (flag for the tax accountant). Overseas direct investment report before capital moves (any stake 10% or more, any amount).

Sheet SKU Unit Economics
A1: SKU Unit Economics
A2: FOB China = H2 landed Korea cost in KRW divided by FX times the FOB factor. Duty columns use the duty table. Air and ocean landed costs use the active duty scenario. Hero row highlighted.
A4: SKU | B4: Spec (internal only) | C4: Length m | D4: H2 cost KRW | E4: FOB USD | F4: US list | G4: US sale price (ASP) | H4: Packaged lb | I4: kg | J4: Air freight | K4: Ocean freight | L4: Duty copper | M4: Duty fiber | N4: Duty stress | O4: Duty active | P4: MPF and HMF (ocean) | Q4: Broker and bond | R4: FBA inbound and prep | S4: QC and labels | T4: Landed air | U4: Landed ocean | V4: Landed air % | W4: Landed ocean % | X4: FBA fee | Y4: Referral 15% | Z4: Ads | AA4: Returns and storage | AB4: Net air | AC4: Net air % | AD4: Net ocean | AE4: Net ocean % | AF4: Launch SKU
A5: 8K_7M | B5: HDMI 2.1 8K hybrid AOC | C5: 7 | D5: 10525 | E5: =D5/FXRate*$B$18 -> 6.7713287 | F5: 49.99 | G5: 39.99 | H5: 0.35 | I5: =H5*$B$21 -> 0.15876 | J5: =I5*$B$19 -> 1.34946 | K5: =I5*$B$20 -> 0.174636 | L5: =E5*'Landed Cost & Tariff Scenarios'!$G$5 -> 2.7153028 | M5: =E5*'Landed Cost & Tariff Scenarios'!$G$6 -> 0.84641608 | N5: =E5*'Landed Cost & Tariff Scenarios'!$G$7 -> 3.3924357 | O5: =INDEX(L5:N5,1,DutyScenario) -> 2.7153028 | P5: =E5*$B$22 -> 0.02369965 | Q5: =$B$23 -> 0.4 | R5: =$B$24 -> 0.5 | S5: =$B$25 -> 0.25 | T5: =E5+J5+O5+Q5+R5+S5 -> 11.986091 | U5: =E5+K5+O5+P5+Q5+R5+S5 -> 10.834967 | V5: =T5/G5 -> 0.29972722 | W5: =U5/G5 -> 0.27094191 | X5: 4.9 | Y5: =G5*Assumptions!$F$19 -> 5.9985 | Z5: =G5*$B$26 -> 4.7988 | AA5: =G5*$B$27 -> 1.9995 | AB5: =G5-T5-X5-Y5-Z5-AA5 -> 10.307109 | AC5: =AB5/G5 -> 0.25774215 | AD5: =G5-U5-X5-Y5-Z5-AA5 -> 11.458233 | AE5: =AD5/G5 -> 0.28652745 | AF5: Yes
A6: 8K_10M | B6: HDMI 2.1 8K hybrid AOC (hero) | C6: 10 | D6: 11470 | E6: =D6/FXRate*$B$18 -> 7.3793007 | F6: 59.99 | G6: 44.99 | H6: 0.45 | I6: =H6*$B$21 -> 0.20412 | J6: =I6*$B$19 -> 1.73502 | K6: =I6*$B$20 -> 0.224532 | L6: =E6*'Landed Cost & Tariff Scenarios'!$G$5 -> 2.9590996 | M6: =E6*'Landed Cost & Tariff Scenarios'!$G$6 -> 0.92241259 | N6: =E6*'Landed Cost & Tariff Scenarios'!$G$7 -> 3.6970297 | O6: =INDEX(L6:N6,1,DutyScenario) -> 2.9590996 | P6: =E6*$B$22 -> 0.025827552 | Q6: =$B$23 -> 0.4 | R6: =$B$24 -> 0.5 | S6: =$B$25 -> 0.25 | T6: =E6+J6+O6+Q6+R6+S6 -> 13.22342 | U6: =E6+K6+O6+P6+Q6+R6+S6 -> 11.73876 | V6: =T6/G6 -> 0.2939191 | W6: =U6/G6 -> 0.26091931 | X6: 4.9 | Y6: =G6*Assumptions!$F$19 -> 6.7485 | Z6: =G6*$B$26 -> 5.3988 | AA6: =G6*$B$27 -> 2.2495 | AB6: =G6-T6-X6-Y6-Z6-AA6 -> 12.46978 | AC6: =AB6/G6 -> 0.27716781 | AD6: =G6-U6-X6-Y6-Z6-AA6 -> 13.95444 | AE6: =AD6/G6 -> 0.3101676 | AF6: Yes
A7: 8K_15M | B7: HDMI 2.1 8K hybrid AOC | C7: 15 | D7: 13376 | E7: =D7/FXRate*$B$18 -> 8.6055385 | F7: 69.99 | G7: 54.99 | H7: 0.6 | I7: =H7*$B$21 -> 0.27216 | J7: =I7*$B$19 -> 2.31336 | K7: =I7*$B$20 -> 0.299376 | L7: =E7*'Landed Cost & Tariff Scenarios'!$G$5 -> 3.4508209 | M7: =E7*'Landed Cost & Tariff Scenarios'!$G$6 -> 1.0756923 | N7: =E7*'Landed Cost & Tariff Scenarios'!$G$7 -> 4.3113748 | O7: =INDEX(L7:N7,1,DutyScenario) -> 3.4508209 | P7: =E7*$B$22 -> 0.030119385 | Q7: =$B$23 -> 0.4 | R7: =$B$24 -> 0.5 | S7: =$B$25 -> 0.25 | T7: =E7+J7+O7+Q7+R7+S7 -> 15.519719 | U7: =E7+K7+O7+P7+Q7+R7+S7 -> 13.535855 | V7: =T7/G7 -> 0.28222803 | W7: =U7/G7 -> 0.24615121 | X7: 5.5 | Y7: =G7*Assumptions!$F$19 -> 8.2485 | Z7: =G7*$B$26 -> 6.5988 | AA7: =G7*$B$27 -> 2.7495 | AB7: =G7-T7-X7-Y7-Z7-AA7 -> 16.373481 | AC7: =AB7/G7 -> 0.29775378 | AD7: =G7-U7-X7-Y7-Z7-AA7 -> 18.357345 | AE7: =AD7/G7 -> 0.33383061 | AF7: Yes
A8: 8K_20M | B8: HDMI 2.1 8K hybrid AOC | C8: 20 | D8: 15266 | E8: =D8/FXRate*$B$18 -> 9.8214825 | F8: 79.99 | G8: 64.99 | H8: 0.75 | I8: =H8*$B$21 -> 0.3402 | J8: =I8*$B$19 -> 2.8917 | K8: =I8*$B$20 -> 0.37422 | L8: =E8*'Landed Cost & Tariff Scenarios'!$G$5 -> 3.9384145 | M8: =E8*'Landed Cost & Tariff Scenarios'!$G$6 -> 1.2276853 | N8: =E8*'Landed Cost & Tariff Scenarios'!$G$7 -> 4.9205627 | O8: =INDEX(L8:N8,1,DutyScenario) -> 3.9384145 | P8: =E8*$B$22 -> 0.034375189 | Q8: =$B$23 -> 0.4 | R8: =$B$24 -> 0.5 | S8: =$B$25 -> 0.25 | T8: =E8+J8+O8+Q8+R8+S8 -> 17.801597 | U8: =E8+K8+O8+P8+Q8+R8+S8 -> 15.318492 | V8: =T8/G8 -> 0.27391286 | W8: =U8/G8 -> 0.23570537 | X8: 5.5 | Y8: =G8*Assumptions!$F$19 -> 9.7485 | Z8: =G8*$B$26 -> 7.7988 | AA8: =G8*$B$27 -> 3.2495 | AB8: =G8-T8-X8-Y8-Z8-AA8 -> 20.891603 | AC8: =AB8/G8 -> 0.32145873 | AD8: =G8-U8-X8-Y8-Z8-AA8 -> 23.374708 | AE8: =AD8/G8 -> 0.35966622 | AF8: Yes
A9: 8K_25M | B9: HDMI 2.1 8K hybrid AOC | C9: 25 | D9: 17172 | E9: =D9/FXRate*$B$18 -> 11.04772 | F9: 89.99 | G9: 74.99 | H9: 0.9 | I9: =H9*$B$21 -> 0.40824 | J9: =I9*$B$19 -> 3.47004 | K9: =I9*$B$20 -> 0.449064 | L9: =E9*'Landed Cost & Tariff Scenarios'!$G$5 -> 4.4301358 | M9: =E9*'Landed Cost & Tariff Scenarios'!$G$6 -> 1.380965 | N9: =E9*'Landed Cost & Tariff Scenarios'!$G$7 -> 5.5349079 | O9: =INDEX(L9:N9,1,DutyScenario) -> 4.4301358 | P9: =E9*$B$22 -> 0.038667021 | Q9: =$B$23 -> 0.4 | R9: =$B$24 -> 0.5 | S9: =$B$25 -> 0.25 | T9: =E9+J9+O9+Q9+R9+S9 -> 20.097896 | U9: =E9+K9+O9+P9+Q9+R9+S9 -> 17.115587 | V9: =T9/G9 -> 0.26800768 | W9: =U9/G9 -> 0.22823826 | X9: 6.6 | Y9: =G9*Assumptions!$F$19 -> 11.2485 | Z9: =G9*$B$26 -> 8.9988 | AA9: =G9*$B$27 -> 3.7495 | AB9: =G9-T9-X9-Y9-Z9-AA9 -> 24.295304 | AC9: =AB9/G9 -> 0.32398058 | AD9: =G9-U9-X9-Y9-Z9-AA9 -> 27.277613 | AE9: =AD9/G9 -> 0.36375 | AF9: No
A10: 8K_50M | B10: HDMI 2.1 8K hybrid AOC | C10: 50 | D10: 27349 | E10: =D10/FXRate*$B$18 -> 17.595161 | F10: 149.99 | G10: 119.99 | H10: 1.9 | I10: =H10*$B$21 -> 0.86184 | J10: =I10*$B$19 -> 7.32564 | K10: =I10*$B$20 -> 0.948024 | L10: =E10*'Landed Cost & Tariff Scenarios'!$G$5 -> 7.0556595 | M10: =E10*'Landed Cost & Tariff Scenarios'!$G$6 -> 2.1993951 | N10: =E10*'Landed Cost & Tariff Scenarios'!$G$7 -> 8.8151756 | O10: =INDEX(L10:N10,1,DutyScenario) -> 7.0556595 | P10: =E10*$B$22 -> 0.061583063 | Q10: =$B$23 -> 0.4 | R10: =$B$24 -> 0.5 | S10: =$B$25 -> 0.25 | T10: =E10+J10+O10+Q10+R10+S10 -> 33.12646 | U10: =E10+K10+O10+P10+Q10+R10+S10 -> 26.810427 | V10: =T10/G10 -> 0.27607684 | W10: =U10/G10 -> 0.22343885 | X10: 8.4 | Y10: =G10*Assumptions!$F$19 -> 17.9985 | Z10: =G10*$B$26 -> 14.3988 | AA10: =G10*$B$27 -> 5.9995 | AB10: =G10-T10-X10-Y10-Z10-AA10 -> 40.06674 | AC10: =AB10/G10 -> 0.33391732 | AD10: =G10-U10-X10-Y10-Z10-AA10 -> 46.382773 | AE10: =AD10/G10 -> 0.38655532 | AF10: No
A11: 4K_15M | B11: HDMI 2.0 4K hybrid AOC | C11: 15 | D11: 12680 | E11: =D11/FXRate*$B$18 -> 8.1577622 | F11: 44.99 | G11: 34.99 | H11: 0.6 | I11: =H11*$B$21 -> 0.27216 | J11: =I11*$B$19 -> 2.31336 | K11: =I11*$B$20 -> 0.299376 | L11: =E11*'Landed Cost & Tariff Scenarios'!$G$5 -> 3.2712627 | M11: =E11*'Landed Cost & Tariff Scenarios'!$G$6 -> 1.0197203 | N11: =E11*'Landed Cost & Tariff Scenarios'!$G$7 -> 4.0870389 | O11: =INDEX(L11:N11,1,DutyScenario) -> 3.2712627 | P11: =E11*$B$22 -> 0.028552168 | Q11: =$B$23 -> 0.4 | R11: =$B$24 -> 0.5 | S11: =$B$25 -> 0.25 | T11: =E11+J11+O11+Q11+R11+S11 -> 14.892385 | U11: =E11+K11+O11+P11+Q11+R11+S11 -> 12.906953 | V11: =T11/G11 -> 0.42561832 | W11: =U11/G11 -> 0.36887548 | X11: 5.5 | Y11: =G11*Assumptions!$F$19 -> 5.2485 | Z11: =G11*$B$26 -> 4.1988 | AA11: =G11*$B$27 -> 1.7495 | AB11: =G11-T11-X11-Y11-Z11-AA11 -> 3.4008151 | AC11: =AB11/G11 -> 0.097193916 | AD11: =G11-U11-X11-Y11-Z11-AA11 -> 5.3862469 | AE11: =AD11/G11 -> 0.15393675 | AF11: No
A12: 4K_20M | B12: HDMI 2.0 4K hybrid AOC | C12: 20 | D12: 14122 | E12: =D12/FXRate*$B$18 -> 9.0854825 | F12: 49.99 | G12: 39.99 | H12: 0.75 | I12: =H12*$B$21 -> 0.3402 | J12: =I12*$B$19 -> 2.8917 | K12: =I12*$B$20 -> 0.37422 | L12: =E12*'Landed Cost & Tariff Scenarios'!$G$5 -> 3.6432785 | M12: =E12*'Landed Cost & Tariff Scenarios'!$G$6 -> 1.1356853 | N12: =E12*'Landed Cost & Tariff Scenarios'!$G$7 -> 4.5518267 | O12: =INDEX(L12:N12,1,DutyScenario) -> 3.6432785 | P12: =E12*$B$22 -> 0.031799189 | Q12: =$B$23 -> 0.4 | R12: =$B$24 -> 0.5 | S12: =$B$25 -> 0.25 | T12: =E12+J12+O12+Q12+R12+S12 -> 16.770461 | U12: =E12+K12+O12+P12+Q12+R12+S12 -> 14.28478 | V12: =T12/G12 -> 0.41936637 | W12: =U12/G12 -> 0.35720881 | X12: 5.5 | Y12: =G12*Assumptions!$F$19 -> 5.9985 | Z12: =G12*$B$26 -> 4.7988 | AA12: =G12*$B$27 -> 1.9995 | AB12: =G12-T12-X12-Y12-Z12-AA12 -> 4.922739 | AC12: =AB12/G12 -> 0.12309925 | AD12: =G12-U12-X12-Y12-Z12-AA12 -> 7.4084198 | AE12: =AD12/G12 -> 0.18525681 | AF12: No
A13: 4K_30M | B13: HDMI 2.0 4K hybrid AOC | C13: 30 | D13: 19542 | E13: =D13/FXRate*$B$18 -> 12.572476 | F13: 64.99 | G13: 49.99 | H13: 1.1 | I13: =H13*$B$21 -> 0.49896 | J13: =I13*$B$19 -> 4.24116 | K13: =I13*$B$20 -> 0.548856 | L13: =E13*'Landed Cost & Tariff Scenarios'!$G$5 -> 5.0415627 | M13: =E13*'Landed Cost & Tariff Scenarios'!$G$6 -> 1.5715594 | N13: =E13*'Landed Cost & Tariff Scenarios'!$G$7 -> 6.2988102 | O13: =INDEX(L13:N13,1,DutyScenario) -> 5.0415627 | P13: =E13*$B$22 -> 0.044003664 | Q13: =$B$23 -> 0.4 | R13: =$B$24 -> 0.5 | S13: =$B$25 -> 0.25 | T13: =E13+J13+O13+Q13+R13+S13 -> 23.005198 | U13: =E13+K13+O13+P13+Q13+R13+S13 -> 19.356898 | V13: =T13/G13 -> 0.460196 | W13: =U13/G13 -> 0.3872154 | X13: 6.6 | Y13: =G13*Assumptions!$F$19 -> 7.4985 | Z13: =G13*$B$26 -> 5.9988 | AA13: =G13*$B$27 -> 2.4995 | AB13: =G13-T13-X13-Y13-Z13-AA13 -> 4.3880018 | AC13: =AB13/G13 -> 0.087777591 | AD13: =G13-U13-X13-Y13-Z13-AA13 -> 8.0363021 | AE13: =AD13/G13 -> 0.16075819 | AF13: Yes
A14: 4K_40M | B14: HDMI 2.0 4K hybrid AOC | C14: 40 | D14: 22609 | E14: =D14/FXRate*$B$18 -> 14.54565 | F14: 74.99 | G14: 59.99 | H14: 1.5 | I14: =H14*$B$21 -> 0.6804 | J14: =I14*$B$19 -> 5.7834 | K14: =I14*$B$20 -> 0.74844 | L14: =E14*'Landed Cost & Tariff Scenarios'!$G$5 -> 5.8328058 | M14: =E14*'Landed Cost & Tariff Scenarios'!$G$6 -> 1.8182063 | N14: =E14*'Landed Cost & Tariff Scenarios'!$G$7 -> 7.2873708 | O14: =INDEX(L14:N14,1,DutyScenario) -> 5.8328058 | P14: =E14*$B$22 -> 0.050909776 | Q14: =$B$23 -> 0.4 | R14: =$B$24 -> 0.5 | S14: =$B$25 -> 0.25 | T14: =E14+J14+O14+Q14+R14+S14 -> 27.311856 | U14: =E14+K14+O14+P14+Q14+R14+S14 -> 22.327806 | V14: =T14/G14 -> 0.45527348 | W14: =U14/G14 -> 0.37219213 | X14: 8.4 | Y14: =G14*Assumptions!$F$19 -> 8.9985 | Z14: =G14*$B$26 -> 7.1988 | AA14: =G14*$B$27 -> 2.9995 | AB14: =G14-T14-X14-Y14-Z14-AA14 -> 5.0813439 | AC14: =AB14/G14 -> 0.084703182 | AD14: =G14-U14-X14-Y14-Z14-AA14 -> 10.065394 | AE14: =AD14/G14 -> 0.16778453 | AF14: No
A15: Basis: H2 cost KRW evidence based (August deal). FOB factor, freight, fees, weights, US prices and FBA fees are management estimates pending the Amazon rate card check. The spec column is internal: packaging and listings use the category names (Ultra High Speed HDMI Cable; Premium High Speed HDMI Cable pending certification).
A17: Cost build constants
A18: FOB factor on the H2 Korea landed cost (removes Korea inbound freight and handling) | B18: 0.92 | C18: Management estimate
A19: Air freight DDP per kg packaged | B19: 8.5 | C19: Management estimate | D19: consolidated express, first lots
A20: Ocean LCL plus drayage per kg packaged | B20: 1.1 | C20: Management estimate
A21: Kilograms per pound | B21: 0.4536 | C21: Evidence based
A22: Merchandise processing and harbor maintenance fees, % of FOB, ocean only | B22: 0.0035 | C22: Management estimate
A23: Broker entry fee and continuous bond, amortized per unit | B23: 0.4 | C23: Management estimate | D23: $150 per entry plus $500 per year bond at launch volumes
A24: FBA inbound placement and prep per unit | B24: 0.5 | C24: Management estimate
A25: Third party QC and FNSKU labeling at the factory per unit | B25: 0.25 | C25: Management estimate
A26: Advertising % of price for unit economics (August hero: $5.40 on $44.99) | B26: 0.12 | C26: Evidence based
A27: Returns and storage reserve % of price (3% returns plus 2% storage and inbound) | B27: 0.05 | C27: Evidence based
A28: FBA fee used in the August hero unit economics | B28: 5.5 | C28: Evidence based
A29: Alibaba benchmark FOB, low, comparable 30 ft (9 m) AOC | B29: 17 | C29: Evidence based | D29: quote, flagged
A30: Alibaba benchmark FOB, high | B30: 22 | C30: Evidence based | D30: quote, flagged
A32: Hero SKU unit economics, August model (evidence based): 8K AOC 10M on Amazon US
A33: Price | B33: 44.99
A34: List price | B34: 59.99
A35: Landed cost % (assumed 38% pending the customs ruling) | B35: 0.38
A36: Landed cost | B36: =B33*B35 -> 17.0962
A37: Referral % | B37: =Assumptions!$F$19 -> 0.15
A38: Referral | B38: =B33*B37 -> 6.7485
A39: FBA fulfillment | B39: =$B$28 -> 5.5
A40: Advertising % (blended) | B40: =$B$26 -> 0.12
A41: Advertising | B41: =B33*B40 -> 5.3988
A42: Returns and storage reserve % | B42: =$B$27 -> 0.05
A43: Returns and storage reserve | B43: =B33*B42 -> 2.2495
...

Sheet Landed Cost & Tariff Scenarios
A1: Landed Cost and Tariff Scenarios
A2: Duty is a selector (DutyScenario on Assumptions). The 12.5% Section 301 forced labor rate applies whichever classification the CBP binding ruling gives.
A4: Scenario | B4: HTS | C4: MFN | D4: Section 301 list rate | E4: Section 301 forced labor (late July 2026) | F4: Pending second Section 301 action | G4: Total duty rate | H4: Basis
A5: Copper | B5: 8544.42.90 | C5: 0.026 | D5: 0.25 | E5: 0.125 | F5: 0 | G5: =SUM(C5:F5) -> 0.401 | H5: Evidence based
A6: Fiber | B6: 8544.70.00 | C6: 0 | D6: 0 | E6: 0.125 | F6: 0 | G6: =SUM(C6:F6) -> 0.125 | H6: Evidence based rates; List 3 coverage of 8544.70.00 is a broker check [PLACEHOLDER]
A7: Stress | B7: 8544.42.90 plus pending second Section 301 action | C7: 0.026 | D7: 0.25 | E7: 0.125 | F7: 0.1 | G7: =SUM(C7:F7) -> 0.501 | H7: Management estimate
A8: Fiber if also on List 3 (check row only, not selectable) | B8: 8544.70.00 | C8: 0 | D8: 0.25 | E8: 0.125 | F8: 0 | G8: =SUM(C8:F8) -> 0.375 | H8: Shown as a check row only
A9: Active duty rate (selected scenario) | G9: =INDEX($G$5:$G$7,DutyScenario,1) -> 0.401
A10: Copper rate (the rate embedded in the base landed COGS %) | G10: =$G$5 -> 0.401
A12: Landed COGS % build for the active scenario (P&L)
A13: Base landed COGS % (Assumptions, Active: Low 43%, Medium 38%, High 32%) | C13: =Assumptions!$F$11 -> 0.38
A14: Duty delta = (active duty rate minus copper rate) times hero FOB share of price | C14: =(DutyRateActive-DutyRateCopper)*HeroFobShare -> 0
A15: Freight mode delta (points; 0 because the base already assumes air then ocean; the Year 2 landed change carries the ocean benefit) | C15: 0
A16: FX delta = hero FOB share times (FX embedded in the cost base divided by FXRate, minus 1) | C16: =HeroFobShare*(Assumptions!$F$111/FXRate-1) -> 0
A17: Active landed COGS % used by the P&L | C17: =C13+C14+C15+C16 -> 0.38
A18: Note: the High base of 32% already assumes the fiber ruling, ocean freight and volume pricing. Selecting Fiber duty with High counts the ruling twice. Use Medium plus Fiber to see the ruling effect (about 33.5%, the August lever 38% to 33%).
A20: Landed COGS % by scenario and duty scenario at the active FX rate (used by the Scenario Summary engines)
A21: Scenario | B21: Copper | C21: Fiber | D21: Stress | E21: At active duty | F21: Hero net per unit at active duty (August fees, $44.99)
A22: Low | B22: =Assumptions!$C$11+($G$5-DutyRateCopper)*HeroFobShare+LandedFreightDelta+LandedFxDelta -> 0.43 | C22: =Assumptions!$C$11+($G$6-DutyRateCopper)*HeroFobShare+LandedFreightDelta+LandedFxDelta -> 0.38473023 | D22: =Assumptions!$C$11+($G$7-DutyRateCopper)*HeroFobShare+LandedFreightDelta+LandedFxDelta -> 0.44640209 | E22: =INDEX(B22:D22,1,DutyScenario) -> 0.43 | F22: =ue_hero_price*(1-E22)-ue_hero_referral-ue_hero_fba-ue_hero_ads-ue_hero_returns_storage -> 5.7475
A23: Medium | B23: =Assumptions!$D$11+($G$5-DutyRateCopper)*HeroFobShare+LandedFreightDelta+LandedFxDelta -> 0.38 | C23: =Assumptions!$D$11+($G$6-DutyRateCopper)*HeroFobShare+LandedFreightDelta+LandedFxDelta -> 0.33473023 | D23: =Assumptions!$D$11+($G$7-DutyRateCopper)*HeroFobShare+LandedFreightDelta+LandedFxDelta -> 0.39640209 | E23: =INDEX(B23:D23,1,DutyScenario) -> 0.38 | F23: =ue_hero_price*(1-E23)-ue_hero_referral-ue_hero_fba-ue_hero_ads-ue_hero_returns_storage -> 7.997
A24: High | B24: =Assumptions!$E$11+($G$5-DutyRateCopper)*HeroFobShare+LandedFreightDelta+LandedFxDelta -> 0.32 | C24: =Assumptions!$E$11+($G$6-DutyRateCopper)*HeroFobShare+LandedFreightDelta+LandedFxDelta -> 0.27473023 | D24: =Assumptions!$E$11+($G$7-DutyRateCopper)*HeroFobShare+LandedFreightDelta+LandedFxDelta -> 0.33640209 | E24: =INDEX(B24:D24,1,DutyScenario) -> 0.32 | F24: =ue_hero_price*(1-E24)-ue_hero_referral-ue_hero_fba-ue_hero_ads-ue_hero_returns_storage -> 10.6964
A26: Hero net per unit by duty scenario (Medium base 38%, August fees, price $44.99) and the waterfall data for the chart
A27: Duty scenario | B27: Duty rate | C27: Landed % | D27: Hero net per unit | E27: Waterfall label | F27: Invisible base | G27: Bar value | H27: Bar color
A28: Copper | B28: =$G$5 -> 0.401 | C28: =B23 -> 0.38 | D28: =ue_hero_price*(1-C28)-ue_hero_referral-ue_hero_fba-ue_hero_ads-ue_hero_returns_storage -> 7.997
A29: Fiber | B29: =$G$6 -> 0.125 | C29: =C23 -> 0.33473023 | D29: =ue_hero_price*(1-C29)-ue_hero_referral-ue_hero_fba-ue_hero_ads-ue_hero_returns_storage -> 10.033687
A30: Stress | B30: =$G$7 -> 0.501 | C30: =D23 -> 0.39640209 | D30: =ue_hero_price*(1-C30)-ue_hero_referral-ue_hero_fba-ue_hero_ads-ue_hero_returns_storage -> 7.2590699
E31: Copper net | F31: =0 -> 0 | G31: =D28 -> 7.997 | H31: value
E32: Fiber ruling uplift | F32: =D28 -> 7.997 | G32: =D29-D28 -> 2.036687 | H32: up
E33: Fiber net | F33: =0 -> 0 | G33: =D29 -> 10.033687 | H33: value
E34: Stress penalty | F34: =D30 -> 7.2590699 | G34: =D28-D30 -> 0.73793007 | H34: down
E35: Stress net | F35: =0 -> 0 | G35: =D30 -> 7.2590699 | H35: value
A37: Tariff stack by scenario (for the stacked chart)
A38: Scenario | B38: MFN | C38: Section 301 list | D38: Section 301 forced labor | E38: Pending second action | F38: Total
A39: Copper | B39: =C5 -> 0.026 | C39: =D5 -> 0.25 | D39: =E5 -> 0.125 | E39: =F5 -> 0 | F39: =G5 -> 0.401
A40: Fiber | B40: =C6 -> 0 | C40: =D6 -> 0 | D40: =E6 -> 0.125 | E40: =F6 -> 0 | F40: =G6 -> 0.125
A41: Stress | B41: =C7 -> 0.026 | C41: =D7 -> 0.25 | D41: =E7 -> 0.125 | E41: =F7 -> 0.1 | F41: =G7 -> 0.501

Sheet Monthly PL Y1 Y2
A1: Monthly P&L, Years 1 and 2 (Months 1 to 24)
A2: ="Active scenario: "&ScenarioName&". Duty: "&DutyScenarioName&". FX "&TEXT(FXRate,"#,##0")&" KRW per USD. Amazon US rows reproduce the August model through Month 18; Year 2 driver changes start in Month 19; eBay, Walmart and B2B rows start in Month 13." -> Active scenario: Medium. Duty: Copper. FX 1,430 KRW per USD. Amazon US rows reproduce the August model through Month 18; Year 2 driver changes start in Month 19; eBay, Walmart and B2B rows start in Month 13.
A3: Monthly P&L engine, active scenario
A4: Line | B4: Unit | C4: Month 0 (pre launch) | D4: Month 1 | E4: Month 2 | F4: Month 3 | G4: Month 4 | H4: Month 5 | I4: Month 6 | J4: Month 7 | K4: Month 8 | L4: Month 9 | M4: Month 10 | N4: Month 11 | O4: Month 12 | P4: Month 13 | Q4: Month 14 | R4: Month 15 | S4: Month 16 | T4: Month 17 | U4: Month 18 | V4: Month 19 | W4: Month 20 | X4: Month 21 | Y4: Month 22 | Z4: Month 23 | AA4: Month 24 | AB4: Year 1 | AC4: Year 2
A5: Month index | C5: 0 | D5: 1 | E5: 2 | F5: 3 | G5: 4 | H5: 5 | I5: 6 | J5: 7 | K5: 8 | L5: 9 | M5: 10 | N5: 11 | O5: 12 | P5: 13 | Q5: 14 | R5: 15 | S5: 16 | T5: 17 | U5: 18 | V5: 19 | W5: 20 | X5: 21 | Y5: 22 | Z5: 23 | AA5: 24 | AB5: Months 1 to 12 | AC5: Months 13 to 24
A6: Amazon US (Months 1 to 18 reproduce the August model; Year 2 driver changes start in Month 19)
A7: Units sold | B7: units | D7: =Assumptions!$F$137 -> 150 | E7: =Assumptions!$F$138 -> 240 | F7: =Assumptions!$F$139 -> 360 | G7: =Assumptions!$F$140 -> 500 | H7: =Assumptions!$F$141 -> 650 | I7: =Assumptions!$F$142 -> 820 | J7: =Assumptions!$F$143 -> 1000 | K7: =Assumptions!$F$144 -> 1200 | L7: =Assumptions!$F$145 -> 1400 | M7: =Assumptions!$F$146 -> 1600 | N7: =Assumptions!$F$147 -> 1800 | O7: =Assumptions!$F$148 -> 2050 | P7: =Assumptions!$F$149 -> 2250 | Q7: =Assumptions!$F$150 -> 2450 | R7: =Assumptions!$F$151 -> 2600 | S7: =Assumptions!$F$152 -> 2750 | T7: =Assumptions!$F$153 -> 2900 | U7: =Assumptions!$F$154 -> 3050 | V7: =Assumptions!$F$155 -> 3150 | W7: =Assumptions!$F$156 -> 3250 | X7: =Assumptions!$F$157 -> 3350 | Y7: =Assumptions!$F$158 -> 3450 | Z7: =Assumptions!$F$159 -> 3550 | AA7: =Assumptions!$F$160 -> 3650 | AB7: =SUM(D7:O7) -> 11770 | AC7: =SUM(P7:AA7) -> 36400
A8: ASP | B8: $ per unit | D8: =Assumptions!$F$10 -> 42 | E8: =Assumptions!$F$10 -> 42 | F8: =Assumptions!$F$10 -> 42 | G8: =Assumptions!$F$10 -> 42 | H8: =Assumptions!$F$10 -> 42 | I8: =Assumptions!$F$10 -> 42 | J8: =Assumptions!$F$10 -> 42 | K8: =Assumptions!$F$10 -> 42 | ... AA8: =Assumptions!$F$10 -> 42 | AB8: =IF(AB7=0,0,AB9/AB7) -> 42 | AC8: =IF(AC7=0,0,AC9/AC7) -> 42
A9: Revenue | B9: $ | D9: =D7*D8 -> 6300 | E9: =E7*E8 -> 10080 | F9: =F7*F8 -> 15120 | G9: =G7*G8 -> 21000 | H9: =H7*H8 -> 27300 | I9: =I7*I8 -> 34440 | J9: =J7*J8 -> 42000 | K9: =K7*K8 -> 50400 | ... AA9: =AA7*AA8 -> 153300 | AB9: =SUM(D9:O9) -> 494340 | AC9: =SUM(P9:AA9) -> 1528800
A10: Landed COGS | B10: $ | D10: =D9*D30 -> 2394 | E10: =E9*E30 -> 3830.4 | F10: =F9*F30 -> 5745.6 | G10: =G9*G30 -> 7980 | H10: =H9*H30 -> 10374 | I10: =I9*I30 -> 13087.2 | J10: =J9*J30 -> 15960 | K10: =K9*K30 -> 19152 | ... AA10: =AA9*AA30 -> 55954.5 | AB10: =SUM(D10:O10) -> 187849.2 | AC10: =SUM(P10:AA10) -> 568092
A11: Referral fee | B11: $ | D11: =D9*Assumptions!$F$19 -> 945 | E11: =E9*Assumptions!$F$19 -> 1512 | F11: =F9*Assumptions!$F$19 -> 2268 | G11: =G9*Assumptions!$F$19 -> 3150 | H11: =H9*Assumptions!$F$19 -> 4095 | I11: =I9*Assumptions!$F$19 -> 5166 | J11: =J9*Assumptions!$F$19 -> 6300 | K11: =K9*Assumptions!$F$19 -> 7560 | ... AA11: =AA9*Assumptions!$F$19 -> 22995 | AB11: =SUM(D11:O11) -> 74151 | AC11: =SUM(P11:AA11) -> 229320
A12: FBA fulfillment | B12: $ | D12: =D7*D31 -> 825 | E12: =E7*E31 -> 1320 | F12: =F7*F31 -> 1980 | G12: =G7*G31 -> 2750 | H12: =H7*H31 -> 3575 | I12: =I7*I31 -> 4510 | J12: =J7*J31 -> 5500 | K12: =K7*K31 -> 6600 | ... AA12: =AA7*AA31 -> 20677.25 | AB12: =SUM(D12:O12) -> 64735 | AC12: =SUM(P12:AA12) -> 203566
A13: Returns | B13: $ | D13: =D9*D32 -> 189 | E13: =E9*E32 -> 302.4 | F13: =F9*F32 -> 453.6 | G13: =G9*G32 -> 630 | H13: =H9*H32 -> 819 | I13: =I9*I32 -> 1033.2 | J13: =J9*J32 -> 1260 | K13: =K9*K32 -> 1512 | ... AA13: =AA9*AA32 -> 3832.5 | AB13: =SUM(D13:O13) -> 14830.2 | AC13: =SUM(P13:AA13) -> 41580
A14: Storage and inbound | B14: $ | D14: =D9*Assumptions!$F$21 -> 126 | E14: =E9*Assumptions!$F$21 -> 201.6 | F14: =F9*Assumptions!$F$21 -> 302.4 | G14: =G9*Assumptions!$F$21 -> 420 | H14: =H9*Assumptions!$F$21 -> 546 | I14: =I9*Assumptions!$F$21 -> 688.8 | J14: =J9*Assumptions!$F$21 -> 840 | K14: =K9*Assumptions!$F$21 -> 1008 | ... AA14: =AA9*Assumptions!$F$21 -> 3066 | AB14: =SUM(D14:O14) -> 9886.8 | AC14: =SUM(P14:AA14) -> 30576
A15: Advertising | B15: $ | D15: =D9*D33 -> 1890 | E15: =E9*E33 -> 3024 | F15: =F9*F33 -> 4536 | G15: =G9*G33 -> 4620 | H15: =H9*H33 -> 6006 | I15: =I9*I33 -> 7576.8 | J15: =J9*J33 -> 6300 | K15: =K9*K33 -> 7560 | ... AA15: =AA9*AA33 -> 16863 | AB15: =SUM(D15:O15) -> 84667.8 | AC15: =SUM(P15:AA15) -> 168168
A16: Contribution, Amazon US (after advertising) | B16: $ | D16: =D9-D10-D11-D12-D13-D14-D15 -> -69 | E16: =E9-E10-E11-E12-E13-E14-E15 -> -110.4 | F16: =F9-F10-F11-F12-F13-F14-F15 -> -165.6 | G16: =G9-G10-G11-G12-G13-G14-G15 -> 1450 | H16: =H9-H10-H11-H12-H13-H14-H15 -> 1885 | I16: =I9-I10-I11-I12-I13-I14-I15 -> 2378 | J16: =J9-J10-J11-J12-J13-J14-J15 -> 5840 | K16: =K9-K10-K11-K12-K13-K14-K15 -> 7008 | ... AA16: =AA9-AA10-AA11-AA12-AA13-AA14-AA15 -> 29911.75 | AB16: =SUM(D16:O16) -> 58220 | AC16: =SUM(P16:AA16) -> 287498
A17: Fixed (software, insurance, misc; people from Year 3) | B17: $ | D17: =IF(D$5>=Assumptions!$F$26,Assumptions!$F$45,Assumptions!$F$17) -> 850 | E17: =IF(E$5>=Assumptions!$F$26,Assumptions!$F$45,Assumptions!$F$17) -> 850 | F17: =IF(F$5>=Assumptions!$F$26,Assumptions!$F$45,Assumptions!$F$17) -> 850 | G17: =IF(G$5>=Assumptions!$F$26,Assumptions!$F$45,Assumptions!$F$17) -> 850 | H17: =IF(H$5>=Assumptions!$F$26,Assumptions!$F$45,Assumptions!$F$17) -> 850 | I17: =IF(I$5>=Assumptions!$F$26,Assumptions!$F$45,Assumptions!$F$17) -> 850 | J17: =IF(J$5>=Assumptions!$F$26,Assumptions!$F$45,Assumptions!$F$17) -> 850 | K17: =IF(K$5>=Assumptions!$F$26,Assumptions!$F$45,Assumptions!$F$17) -> 850 | ... AA17: =IF(AA$5>=Assumptions!$F$26,Assumptions!$F$45,Assumptions!$F$17) -> 1500 | AB17: =SUM(D17:O17) -> 10200 | AC17: =SUM(P17:AA17) -> 14100
A18: Professional seller fee | B18: $ | D18: =Assumptions!$F$22 -> 39.99 | E18: =Assumptions!$F$22 -> 39.99 | F18: =Assumptions!$F$22 -> 39.99 | G18: =Assumptions!$F$22 -> 39.99 | H18: =Assumptions!$F$22 -> 39.99 | I18: =Assumptions!$F$22 -> 39.99 | J18: =Assumptions!$F$22 -> 39.99 | K18: =Assumptions!$F$22 -> 39.99 | ... AA18: =Assumptions!$F$22 -> 39.99 | AB18: =SUM(D18:O18) -> 479.88 | AC18: =SUM(P18:AA18) -> 479.88
A19: One time launch costs | B19: $ | D19: =IF(D$5=1,Assumptions!$F$23,0) -> 9500 | E19: =IF(E$5=1,Assumptions!$F$23,0) -> 0 | F19: =IF(F$5=1,Assumptions!$F$23,0) -> 0 | G19: =IF(G$5=1,Assumptions!$F$23,0) -> 0 | H19: =IF(H$5=1,Assumptions!$F$23,0) -> 0 | I19: =IF(I$5=1,Assumptions!$F$23,0) -> 0 | J19: =IF(J$5=1,Assumptions!$F$23,0) -> 0 | K19: =IF(K$5=1,Assumptions!$F$23,0) -> 0 | ... AA19: =IF(AA$5=1,Assumptions!$F$23,0) -> 0 | AB19: =SUM(D19:O19) -> 9500 | AC19: =SUM(P19:AA19) -> 0
A20: Compliance (Form 5472, Wyoming report, bond, insurance; spread over the months from the Year 2 start month to Month 24) | B20: $ | D20: =IF(D$5>=Assumptions!$F$26,(Assumptions!$F$94+Assumptions!$F$95+Assumptions!$F$96+Assumptions!$F$97)/(24-Assumptions!$F$26+1),0) -> 0 | E20: =IF(E$5>=Assumptions!$F$26,(Assumptions!$F$94+Assumptions!$F$95+Assumptions!$F$96+Assumptions!$F$97)/(24-Assumptions!$F$26+1),0) -> 0 | F20: =IF(F$5>=Assumptions!$F$26,(Assumptions!$F$94+Assumptions!$F$95+Assumptions!$F$96+Assumptions!$F$97)/(24-Assumptions!$F$26+1),0) -> 0 | G20: =IF(G$5>=Assumptions!$F$26,(Assumptions!$F$94+Assumptions!$F$95+Assumptions!$F$96+Assumptions!$F$97)/(24-Assumptions!$F$26+1),0) -> 0 | H20: =IF(H$5>=Assumptions!$F$26,(Assumptions!$F$94+Assumptions!$F$95+Assumptions!$F$96+Assumptions!$F$97)/(24-Assumptions!$F$26+1),0) -> 0 | I20: =IF(I$5>=Assumptions!$F$26,(Assumptions!$F$94+Assumptions!$F$95+Assumptions!$F$96+Assumptions!$F$97)/(24-Assumptions!$F$26+1),0) -> 0 | J20: =IF(J$5>=Assumptions!$F$26,(Assumptions!$F$94+Assumptions!$F$95+Assumptions!$F$96+Assumptions!$F$97)/(24-Assumptions!$F$26+1),0) -> 0 | K20: =IF(K$5>=Assumptions!$F$26,(Assumptions!$F$94+Assumptions!$F$95+Assumptions!$F$96+Assumptions!$F$97)/(24-Assumptions!$F$26+1),0) -> 0 | ... AA20: =IF(AA$5>=Assumptions!$F$26,(Assumptions!$F$94+Assumptions!$F$95+Assumptions!$F$96+Assumptions!$F$97)/(24-Assumptions!$F$26+1),0) -> 426.66667 | AB20: =SUM(D20:O20) -> 0 | AC20: =SUM(P20:AA20) -> 2560
A21: Net, Amazon US after fixed costs (August basis) | B21: $ | D21: =D16-D17-D18-D19-D20 -> -10458.99 | E21: =E16-E17-E18-E19-E20 -> -1000.39 | F21: =F16-F17-F18-F19-F20 -> -1055.59 | G21: =G16-G17-G18-G19-G20 -> 560.01 | H21: =H16-H17-H18-H19-H20 -> 995.01 | I21: =I16-I17-I18-I19-I20 -> 1488.01 | J21: =J16-J17-J18-J19-J20 -> 4950.01 | K21: =K16-K17-K18-K19-K20 -> 6118.01 | ... AA21: =AA16-AA17-AA18-AA19-AA20 -> 27945.093 | AB21: =SUM(D21:O21) -> 38040.12 | AC21: =SUM(P21:AA21) -> 270358.12
A22: Cumulative net | B22: $ | D22: =D21 -> -10458.99 | E22: =D22+E21 -> -11459.38 | F22: =E22+F21 -> -12514.97 | G22: =F22+G21 -> -11954.96 | H22: =G22+H21 -> -10959.95 | I22: =H22+I21 -> -9471.94 | J22: =I22+J21 -> -4521.93 | K22: =J22+K21 -> 1596.08 | L22: =K22+L21 -> 8882.09 | ... AA22: =Z22+AA21 -> 308398.24 | AB22: =O22 -> 38040.12 | AC22: =AA22 -> 308398.24
A23: Net margin | B23: % | D23: =IF(D9=0,0,D21/D9) -> -1.6601571 | E23: =IF(E9=0,0,E21/E9) -> -0.09924504 | F23: =IF(F9=0,0,F21/F9) -> -0.069814153 | G23: =IF(G9=0,0,G21/G9) -> 0.026667143 | H23: =IF(H9=0,0,H21/H9) -> 0.036447253 | I23: =IF(I9=0,0,I21/I9) -> 0.043205865 | J23: =IF(J9=0,0,J21/J9) -> 0.11785738 | K23: =IF(K9=0,0,K21/K9) -> 0.12138909 | ... AC23: =IF(AC9=0,0,AC21/AC9) -> 0.17684335
A24: TACOS (advertising divided by revenue) | B24: % | D24: =IF(D9=0,0,D15/D9) -> 0.3 | E24: =IF(E9=0,0,E15/E9) -> 0.3 | F24: =IF(F9=0,0,F15/F9) -> 0.3 | G24: =IF(G9=0,0,G15/G9) -> 0.22 | H24: =IF(H9=0,0,H15/H9) -> 0.22 | I24: =IF(I9=0,0,I15/I9) -> 0.22 | J24: =IF(J9=0,0,J15/J9) -> 0.15 | K24: =IF(K9=0,0,K15/K9) -> 0.15 | ... AC24: =IF(AC9=0,0,AC15/AC9) -> 0.11
A25: Contribution per unit before advertising | B25: $ per unit | D25: =IF(D7=0,0,(D16+D15)/D7) -> 12.14 | E25: =IF(E7=0,0,(E16+E15)/E7) -> 12.14 | F25: =IF(F7=0,0,(F16+F15)/F7) -> 12.14 | G25: =IF(G7=0,0,(G16+G15)/G7) -> 12.14 | H25: =IF(H7=0,0,(H16+H15)/H7) -> 12.14 | I25: =IF(I7=0,0,(I16+I15)/I7) -> 12.14 | J25: =IF(J7=0,0,(J16+J15)/J7) -> 12.14 | K25: =IF(K7=0,0,(K16+K15)/K7) -> 12.14 | ... AC25: =IF(AC7=0,0,(AC16+AC15)/AC7) -> 12.518297
A26: Contribution per unit after advertising | B26: $ per unit | D26: =IF(D7=0,0,D16/D7) -> -0.46 | E26: =IF(E7=0,0,E16/E7) -> -0.46 | F26: =IF(F7=0,0,F16/F7) -> -0.46 | G26: =IF(G7=0,0,G16/G7) -> 2.9 | H26: =IF(H7=0,0,H16/H7) -> 2.9 | I26: =IF(I7=0,0,I16/I7) -> 2.9 | J26: =IF(J7=0,0,J16/J7) -> 5.84 | K26: =IF(K7=0,0,K16/K7) -> 5.84 | ... AC26: =IF(AC7=0,0,AC16/AC7) -> 7.8982967
A27: Cumulative breakeven flag (1 when cumulative net is at or above 0) | B27: flag | D27: =IF(D22>=0,1,0) -> 0 | E27: =IF(E22>=0,1,0) -> 0 | F27: =IF(F22>=0,1,0) -> 0 | G27: =IF(G22>=0,1,0) -> 0 | H27: =IF(H22>=0,1,0) -> 0 | I27: =IF(I22>=0,1,0) -> 0 | J27: =IF(J22>=0,1,0) -> 0 | K27: =IF(K22>=0,1,0) -> 1 | ... AA27: =IF(AA22>=0,1,0) -> 1
A29: Monthly drivers (from Assumptions)
A30: Landed COGS % of revenue (base plus duty, FX and the Year 2 change from the Year 2 start month) | B30: % | D30: =IF(D$5>=Assumptions!$F$26,LandedPctActive+Assumptions!$F$33,LandedPctActive) -> 0.38 | E30: =IF(E$5>=Assumptions!$F$26,LandedPctActive+Assumptions!$F$33,LandedPctActive) -> 0.38 | F30: =IF(F$5>=Assumptions!$F$26,LandedPctActive+Assumptions!$F$33,LandedPctActive) -> 0.38 | G30: =IF(G$5>=Assumptions!$F$26,LandedPctActive+Assumptions!$F$33,LandedPctActive) -> 0.38 | H30: =IF(H$5>=Assumptions!$F$26,LandedPctActive+Assumptions!$F$33,LandedPctActive) -> 0.38 | I30: =IF(I$5>=Assumptions!$F$26,LandedPctActive+Assumptions!$F$33,LandedPctActive) -> 0.38 | J30: =IF(J$5>=Assumptions!$F$26,LandedPctActive+Assumptions!$F$33,LandedPctActive) -> 0.38 | K30: =IF(K$5>=Assumptions!$F$26,LandedPctActive+Assumptions!$F$33,LandedPctActive) -> 0.38 | ... AA30: =IF(AA$5>=Assumptions!$F$26,LandedPctActive+Assumptions!$F$33,LandedPctActive) -> 0.365 | AB30: =IF(AB9=0,0,AB10/AB9) -> 0.38 | AC30: =IF(AC9=0,0,AC10/AC9) -> 0.37159341
A31: FBA fee per unit (inflation from the Year 2 start month) | B31: $ per unit | D31: =Assumptions!$F$20*IF(D$5>=Assumptions!$F$26,1+Assumptions!$F$32,1) -> 5.5 | E31: =Assumptions!$F$20*IF(E$5>=Assumptions!$F$26,1+Assumptions!$F$32,1) -> 5.5 | F31: =Assumptions!$F$20*IF(F$5>=Assumptions!$F$26,1+Assumptions!$F$32,1) -> 5.5 | G31: =Assumptions!$F$20*IF(G$5>=Assumptions!$F$26,1+Assumptions!$F$32,1) -> 5.5 | H31: =Assumptions!$F$20*IF(H$5>=Assumptions!$F$26,1+Assumptions!$F$32,1) -> 5.5 | I31: =Assumptions!$F$20*IF(I$5>=Assumptions!$F$26,1+Assumptions!$F$32,1) -> 5.5 | J31: =Assumptions!$F$20*IF(J$5>=Assumptions!$F$26,1+Assumptions!$F$32,1) -> 5.5 | K31: =Assumptions!$F$20*IF(K$5>=Assumptions!$F$26,1+Assumptions!$F$32,1) -> 5.5 | ... AA31: =Assumptions!$F$20*IF(AA$5>=Assumptions!$F$26,1+Assumptions!$F$32,1) -> 5.665 | AB31: =IF(AB7=0,0,AB12/AB7) -> 5.5 | AC31: =IF(AC7=0,0,AC12/AC7) -> 5.5924725
A32: Returns % (Year 2 rate from the Year 2 start month) | B32: % | D32: =IF(D$5>=Assumptions!$F$26,Assumptions!$F$31,Assumptions!$F$12) -> 0.03 | E32: =IF(E$5>=Assumptions!$F$26,Assumptions!$F$31,Assumptions!$F$12) -> 0.03 | F32: =IF(F$5>=Assumptions!$F$26,Assumptions!$F$31,Assumptions!$F$12) -> 0.03 | G32: =IF(G$5>=Assumptions!$F$26,Assumptions!$F$31,Assumptions!$F$12) -> 0.03 | H32: =IF(H$5>=Assumptions!$F$26,Assumptions!$F$31,Assumptions!$F$12) -> 0.03 | I32: =IF(I$5>=Assumptions!$F$26,Assumptions!$F$31,Assumptions!$F$12) -> 0.03 | J32: =IF(J$5>=Assumptions!$F$26,Assumptions!$F$31,Assumptions!$F$12) -> 0.03 | K32: =IF(K$5>=Assumptions!$F$26,Assumptions!$F$31,Assumptions!$F$12) -> 0.03 | ... AA32: =IF(AA$5>=Assumptions!$F$26,Assumptions!$F$31,Assumptions!$F$12) -> 0.025 | AB32: =IF(AB9=0,0,AB13/AB9) -> 0.03 | AC32: =IF(AC9=0,0,AC13/AC9) -> 0.027197802
A33: Ad spend % (phases: Months 1 to 3, 4 to 6, 7 to 12, 13 to 18, then the Year 2 start month to 24) | B33: % | D33: =IF(D$5<=3,Assumptions!$F$13,IF(D$5<=6,Assumptions!$F$14,IF(D$5<=12,Assumptions!$F$15,IF(D$5<Assumptions!$F$26,Assumptions!$F$16,Assumptions!$F$27)))) -> 0.3 | E33: =IF(E$5<=3,Assumptions!$F$13,IF(E$5<=6,Assumptions!$F$14,IF(E$5<=12,Assumptions!$F$15,IF(E$5<Assumptions!$F$26,Assumptions!$F$16,Assumptions!$F$27)))) -> 0.3 | F33: =IF(F$5<=3,Assumptions!$F$13,IF(F$5<=6,Assumptions!$F$14,IF(F$5<=12,Assumptions!$F$15,IF(F$5<Assumptions!$F$26,Assumptions!$F$16,Assumptions!$F$27)))) -> 0.3 | G33: =IF(G$5<=3,Assumptions!$F$13,IF(G$5<=6,Assumptions!$F$14,IF(G$5<=12,Assumptions!$F$15,IF(G$5<Assumptions!$F$26,Assumptions!$F$16,Assumptions!$F$27)))) -> 0.22 | H33: =IF(H$5<=3,Assumptions!$F$13,IF(H$5<=6,Assumptions!$F$14,IF(H$5<=12,Assumptions!$F$15,IF(H$5<Assumptions!$F$26,Assumptions!$F$16,Assumptions!$F$27)))) -> 0.22 | I33: =IF(I$5<=3,Assumptions!$F$13,IF(I$5<=6,Assumptions!$F$14,IF(I$5<=12,Assumptions!$F$15,IF(I$5<Assumptions!$F$26,Assumptions!$F$16,Assumptions!$F$27)))) -> 0.22 | J33: =IF(J$5<=3,Assumptions!$F$13,IF(J$5<=6,Assumptions!$F$14,IF(J$5<=12,Assumptions!$F$15,IF(J$5<Assumptions!$F$26,Assumptions!$F$16,Assumptions!$F$27)))) -> 0.15 | K33: =IF(K$5<=3,Assumptions!$F$13,IF(K$5<=6,Assumptions!$F$14,IF(K$5<=12,Assumptions!$F$15,IF(K$5<Assumptions!$F$26,Assumptions!$F$16,Assumptions!$F$27)))) -> 0.15 | ... AA33: =IF(AA$5<=3,Assumptions!$F$13,IF(AA$5<=6,Assumptions!$F$14,IF(AA$5<=12,Assumptions!$F$15,IF(AA$5<Assumptions!$F$26,Assumptions!$F$16,Assumptions!$F$27)))) -> 0.11 | AB33: =IF(AB9=0,0,AB15/AB9) -> 0.17127443 | AC33: =IF(AC9=0,0,AC15/AC9) -> 0.11
A35: Year 2 channels (Months 13 to 24) so Year 2 ties to the annual tab
A36: eBay and Walmart overflow revenue (% of Amazon US revenue) | B36: $ | D36: =IF(D$5>=13,D9*Assumptions!$F$49,0) -> 0 | E36: =IF(E$5>=13,E9*Assumptions!$F$49,0) -> 0 | F36: =IF(F$5>=13,F9*Assumptions!$F$49,0) -> 0 | G36: =IF(G$5>=13,G9*Assumptions!$F$49,0) -> 0 | H36: =IF(H$5>=13,H9*Assumptions!$F$49,0) -> 0 | I36: =IF(I$5>=13,I9*Assumptions!$F$49,0) -> 0 | J36: =IF(J$5>=13,J9*Assumptions!$F$49,0) -> 0 | K36: =IF(K$5>=13,K9*Assumptions!$F$49,0) -> 0 | ... AA36: =IF(AA$5>=13,AA9*Assumptions!$F$49,0) -> 12264 | AB36: =SUM(D36:O36) -> 0 | AC36: =SUM(P36:AA36) -> 122304
A37: eBay and Walmart units | B37: units | D37: =IF(D8=0,0,D36/D8) -> 0 | E37: =IF(E8=0,0,E36/E8) -> 0 | F37: =IF(F8=0,0,F36/F8) -> 0 | G37: =IF(G8=0,0,G36/G8) -> 0 | H37: =IF(H8=0,0,H36/H8) -> 0 | I37: =IF(I8=0,0,I36/I8) -> 0 | J37: =IF(J8=0,0,J36/J8) -> 0 | K37: =IF(K8=0,0,K36/K8) -> 0 | ... AA37: =IF(AA8=0,0,AA36/AA8) -> 292 | AB37: =SUM(D37:O37) -> 0 | AC37: =SUM(P37:AA37) -> 2912
A38: eBay and Walmart landed COGS | B38: $ | D38: =D36*D30 -> 0 | E38: =E36*E30 -> 0 | F38: =F36*F30 -> 0 | G38: =G36*G30 -> 0 | H38: =H36*H30 -> 0 | I38: =I36*I30 -> 0 | J38: =J36*J30 -> 0 | K38: =K36*K30 -> 0 | ... AA38: =AA36*AA30 -> 4476.36 | AB38: =SUM(D38:O38) -> 0 | AC38: =SUM(P38:AA38) -> 45447.36
A39: eBay and Walmart referral | B39: $ | D39: =D36*Assumptions!$F$66 -> 0 | E39: =E36*Assumptions!$F$66 -> 0 | F39: =F36*Assumptions!$F$66 -> 0 | G39: =G36*Assumptions!$F$66 -> 0 | H39: =H36*Assumptions!$F$66 -> 0 | I39: =I36*Assumptions!$F$66 -> 0 | J39: =J36*Assumptions!$F$66 -> 0 | K39: =K36*Assumptions!$F$66 -> 0 | ... AA39: =AA36*Assumptions!$F$66 -> 1594.32 | AB39: =SUM(D39:O39) -> 0 | AC39: =SUM(P39:AA39) -> 15899.52
A40: eBay and Walmart multi channel fulfillment | B40: $ | D40: =D37*Assumptions!$F$67 -> 0 | E40: =E37*Assumptions!$F$67 -> 0 | F40: =F37*Assumptions!$F$67 -> 0 | G40: =G37*Assumptions!$F$67 -> 0 | H40: =H37*Assumptions!$F$67 -> 0 | I40: =I37*Assumptions!$F$67 -> 0 | J40: =J37*Assumptions!$F$67 -> 0 | K40: =K37*Assumptions!$F$67 -> 0 | ... AA40: =AA37*Assumptions!$F$67 -> 1898 | AB40: =SUM(D40:O40) -> 0 | AC40: =SUM(P40:AA40) -> 18928
A41: eBay and Walmart advertising | B41: $ | D41: =D36*Assumptions!$F$68 -> 0 | E41: =E36*Assumptions!$F$68 -> 0 | F41: =F36*Assumptions!$F$68 -> 0 | G41: =G36*Assumptions!$F$68 -> 0 | H41: =H36*Assumptions!$F$68 -> 0 | I41: =I36*Assumptions!$F$68 -> 0 | J41: =J36*Assumptions!$F$68 -> 0 | K41: =K36*Assumptions!$F$68 -> 0 | ... AA41: =AA36*Assumptions!$F$68 -> 613.2 | AB41: =SUM(D41:O41) -> 0 | AC41: =SUM(P41:AA41) -> 6115.2
A42: eBay and Walmart returns | B42: $ | D42: =D36*Assumptions!$F$69 -> 0 | E42: =E36*Assumptions!$F$69 -> 0 | F42: =F36*Assumptions!$F$69 -> 0 | G42: =G36*Assumptions!$F$69 -> 0 | H42: =H36*Assumptions!$F$69 -> 0 | I42: =I36*Assumptions!$F$69 -> 0 | J42: =J36*Assumptions!$F$69 -> 0 | K42: =K36*Assumptions!$F$69 -> 0 | ... AA42: =AA36*Assumptions!$F$69 -> 367.92 | AB42: =SUM(D42:O42) -> 0 | AC42: =SUM(P42:AA42) -> 3669.12
...

Sheet Annual PL Y1 to Y5
A1: Annual P&L, Years 1 to 5 by channel
A2: ="Active scenario: "&ScenarioName&". Years 1 and 2 are sums of the monthly tab (check rows show 0). Years 3 to 5 come from the Year 3 to 5 drivers on Assumptions." -> Active scenario: Medium. Years 1 and 2 are sums of the monthly tab (check rows show 0). Years 3 to 5 come from the Year 3 to 5 drivers on Assumptions.
A3: Annual P&L engine, active scenario
A4: Line | B4: Unit | C4: Year 1 | D4: Year 2 | E4: Year 3 | F4: Year 4 | G4: Year 5 | H4: Basis
A5: Amazon US drivers
A6: Amazon US units | B6: units | C6: ='Monthly PL Y1 Y2'!AB7 -> 11770 | D6: ='Monthly PL Y1 Y2'!AC7 -> 36400 | E6: =D6*(1+Assumptions!$F$37) -> 47320 | F6: =E6*(1+Assumptions!$F$38) -> 56784 | G6: =F6*(1+Assumptions!$F$39) -> 63598.08 | H6: Years 1 and 2 from the monthly tab; then unit growth driver
A7: ASP (Years 3 to 5: yearly change plus the Year 3 roadmap mix uplift) | B7: $ per unit | C7: ='Monthly PL Y1 Y2'!AB8 -> 42 | D7: ='Monthly PL Y1 Y2'!AC8 -> 42 | E7: =D7*(1+Assumptions!$F$40)*IF(3=3,1+Assumptions!$F$41,1) -> 41.5296 | F7: =E7*(1+Assumptions!$F$40)*IF(4=3,1+Assumptions!$F$41,1) -> 39.868416 | G7: =F7*(1+Assumptions!$F$40)*IF(5=3,1+Assumptions!$F$41,1) -> 38.273679
A8: Landed COGS % (active base plus duty, FX and the yearly change) | B8: % | C8: ='Monthly PL Y1 Y2'!AB30 -> 0.38 | D8: ='Monthly PL Y1 Y2'!AC30 -> 0.37159341 | E8: =LandedPctActive+Assumptions!$F$34 -> 0.365 | F8: =LandedPctActive+Assumptions!$F$35 -> 0.37 | G8: =LandedPctActive+Assumptions!$F$36 -> 0.375
A9: Ad spend % of revenue | B9: % | C9: ='Monthly PL Y1 Y2'!AB33 -> 0.17127443 | D9: ='Monthly PL Y1 Y2'!AC33 -> 0.11 | E9: =Assumptions!$F$42 -> 0.115 | F9: =Assumptions!$F$43 -> 0.115 | G9: =Assumptions!$F$44 -> 0.115
A10: Returns % | B10: % | C10: ='Monthly PL Y1 Y2'!AB32 -> 0.03 | D10: ='Monthly PL Y1 Y2'!AC32 -> 0.027197802 | E10: =Assumptions!$F$31 -> 0.025 | F10: =Assumptions!$F$31 -> 0.025 | G10: =Assumptions!$F$31 -> 0.025
A11: FBA fee per unit (3% inflation per year) | B11: $ per unit | C11: ='Monthly PL Y1 Y2'!AB31 -> 5.5 | D11: ='Monthly PL Y1 Y2'!AC31 -> 5.5924725 | E11: =Assumptions!$F$20*(1+Assumptions!$F$32)^(3-1) -> 5.83495 | F11: =Assumptions!$F$20*(1+Assumptions!$F$32)^(4-1) -> 6.0099985 | G11: =Assumptions!$F$20*(1+Assumptions!$F$32)^(5-1) -> 6.1902985
A13: Amazon US
A14: Units | B14: units | C14: ='Monthly PL Y1 Y2'!AB7 -> 11770 | D14: ='Monthly PL Y1 Y2'!AC7 -> 36400 | E14: =E6 -> 47320 | F14: =F6 -> 56784 | G14: =G6 -> 63598.08
A15: Revenue | B15: $ | C15: ='Monthly PL Y1 Y2'!AB9 -> 494340 | D15: ='Monthly PL Y1 Y2'!AC9 -> 1528800 | E15: =E14*E7 -> 1965180.7 | F15: =F14*F7 -> 2263888.1 | G15: =G14*G7 -> 2434132.5
A16: Landed COGS | B16: $ | C16: ='Monthly PL Y1 Y2'!AB10 -> 187849.2 | D16: ='Monthly PL Y1 Y2'!AC10 -> 568092 | E16: =E15*E8 -> 717290.95 | F16: =F15*F8 -> 837638.61 | G16: =G15*G8 -> 912799.7
A17: Channel fees (referral, payment, commission) | B17: $ | C17: ='Monthly PL Y1 Y2'!AB11 -> 74151 | D17: ='Monthly PL Y1 Y2'!AC11 -> 229320 | E17: =E15*Assumptions!$F$19 -> 294777.1 | F17: =F15*Assumptions!$F$19 -> 339583.22 | G17: =G15*Assumptions!$F$19 -> 365119.88
A18: Fulfillment (FBA, MCF, 3PL, shipping) | B18: $ | C18: ='Monthly PL Y1 Y2'!AB12 -> 64735 | D18: ='Monthly PL Y1 Y2'!AC12 -> 203566 | E18: =E14*E11 -> 276109.83 | F18: =F14*F11 -> 341271.75 | G18: =G14*G11 -> 393691.1
A19: Advertising and marketing | B19: $ | C19: ='Monthly PL Y1 Y2'!AB15 -> 84667.8 | D19: ='Monthly PL Y1 Y2'!AC15 -> 168168 | E19: =E15*E9 -> 225995.78 | F19: =F15*F9 -> 260347.14 | G19: =G15*G9 -> 279925.24
A20: Returns and storage | B20: $ | C20: ='Monthly PL Y1 Y2'!AB13+'Monthly PL Y1 Y2'!AB14 -> 24717 | D20: ='Monthly PL Y1 Y2'!AC13+'Monthly PL Y1 Y2'!AC14 -> 72156 | E20: =E15*(E10+Assumptions!$F$21) -> 88433.13 | F20: =F15*(F10+Assumptions!$F$21) -> 101874.97 | G20: =G15*(G10+Assumptions!$F$21) -> 109535.96
A21: Contribution | B21: $ | C21: =C15-C16-C17-C18-C19-C20 -> 58220 | D21: =D15-D16-D17-D18-D19-D20 -> 287498 | E21: =E15-E16-E17-E18-E19-E20 -> 362573.88 | F21: =F15-F16-F17-F18-F19-F20 -> 383172.45 | G21: =G15-G16-G17-G18-G19-G20 -> 373060.65
A22: eBay and Walmart overflow
A23: Units | B23: units | C23: ='Monthly PL Y1 Y2'!AB37 -> 0 | D23: ='Monthly PL Y1 Y2'!AC37 -> 2912 | E23: =IF(E7=0,0,E24/E7) -> 4732 | F23: =IF(F7=0,0,F24/F7) -> 6814.08 | G23: =IF(G7=0,0,G24/G7) -> 7631.7696
A24: Revenue | B24: $ | C24: ='Monthly PL Y1 Y2'!AB36 -> 0 | D24: ='Monthly PL Y1 Y2'!AC36 -> 122304 | E24: =E15*Assumptions!$F$50 -> 196518.07 | F24: =F15*Assumptions!$F$51 -> 271666.58 | G24: =G15*Assumptions!$F$52 -> 292095.9
A25: Landed COGS | B25: $ | C25: ='Monthly PL Y1 Y2'!AB38 -> 0 | D25: ='Monthly PL Y1 Y2'!AC38 -> 45447.36 | E25: =E24*E8 -> 71729.095 | F25: =F24*F8 -> 100516.63 | G25: =G24*G8 -> 109535.96
A26: Channel fees (referral, payment, commission) | B26: $ | C26: ='Monthly PL Y1 Y2'!AB39 -> 0 | D26: ='Monthly PL Y1 Y2'!AC39 -> 15899.52 | E26: =E24*Assumptions!$F$66 -> 25547.349 | F26: =F24*Assumptions!$F$66 -> 35316.655 | G26: =G24*Assumptions!$F$66 -> 37972.467
A27: Fulfillment (FBA, MCF, 3PL, shipping) | B27: $ | C27: ='Monthly PL Y1 Y2'!AB40 -> 0 | D27: ='Monthly PL Y1 Y2'!AC40 -> 18928 | E27: =E23*Assumptions!$F$67 -> 30758 | F27: =F23*Assumptions!$F$67 -> 44291.52 | G27: =G23*Assumptions!$F$67 -> 49606.502
A28: Advertising and marketing | B28: $ | C28: ='Monthly PL Y1 Y2'!AB41 -> 0 | D28: ='Monthly PL Y1 Y2'!AC41 -> 6115.2 | E28: =E24*Assumptions!$F$68 -> 9825.9034 | F28: =F24*Assumptions!$F$68 -> 13583.329 | G28: =G24*Assumptions!$F$68 -> 14604.795
A29: Returns and storage | B29: $ | C29: ='Monthly PL Y1 Y2'!AB42 -> 0 | D29: ='Monthly PL Y1 Y2'!AC42 -> 3669.12 | E29: =E24*Assumptions!$F$69 -> 5895.542 | F29: =F24*Assumptions!$F$69 -> 8149.9973 | G29: =G24*Assumptions!$F$69 -> 8762.8771
A30: Contribution | B30: $ | C30: =C24-C25-C26-C27-C28-C29 -> 0 | D30: =D24-D25-D26-D27-D28-D29 -> 32244.8 | E30: =E24-E25-E26-E27-E28-E29 -> 52762.179 | F30: =F24-F25-F26-F27-F28-F29 -> 69808.442 | G30: =G24-G25-G26-G27-G28-G29 -> 71613.297
A31: B2B installer and AV integrator
A32: Units | B32: units | C32: ='Monthly PL Y1 Y2'!AB45 -> 0 | D32: ='Monthly PL Y1 Y2'!AC45 -> 4761.9048 | E32: =IF(E7=0,0,E33/(E7*Assumptions!$F$70)) -> 14046.206 | F32: =IF(F7=0,0,F33/(F7*Assumptions!$F$70)) -> 25082.511 | G32: =IF(G7=0,0,G33/(G7*Assumptions!$F$70)) -> 37014.123
A33: Revenue | B33: $ | C33: ='Monthly PL Y1 Y2'!AB44 -> 0 | D33: ='Monthly PL Y1 Y2'!AC44 -> 120000 | E33: =Assumptions!$F$54 -> 350000 | F33: =Assumptions!$F$55 -> 600000 | G33: =Assumptions!$F$56 -> 850000
A34: Landed COGS | B34: $ | C34: ='Monthly PL Y1 Y2'!AB46 -> 0 | D34: ='Monthly PL Y1 Y2'!AC46 -> 74500 | E34: =E32*E7*E8 -> 212916.67 | F34: =F32*F7*F8 -> 370000 | G34: =G32*G7*G8 -> 531250
A35: Channel fees (referral, payment, commission) | B35: $ | C35: ='Monthly PL Y1 Y2'!AB48 -> 0 | D35: ='Monthly PL Y1 Y2'!AC48 -> 6000 | E35: =E33*Assumptions!$F$72 -> 17500 | F35: =F33*Assumptions!$F$72 -> 30000 | G35: =G33*Assumptions!$F$72 -> 42500
