Workbook

Sheet Cover
A1: 08 Risk Register: BRAND LLC US launch
A2: Built October 8, 2026. Generator build/build_risk.py. Model numbers from build/figures.json (pulled from output/03_Financial_Model_5Y.xlsx), facts from build/facts.json.
A4: Purpose | B4: Every risk that can stop the launch or the 5 year plan, scored for probability and impact, with the early warning signal to watch, the mitigation, the owner, the trigger that forces action, and whether the risk is tied to one of the explicit kill criteria that stop further capital.
A5: How to use | B5: Work in the Risk Register tab. Change only the yellow cells (Probability, Impact, Kill criterion if the gate rules change). Score, rank, the Heat Map and the Kill Criteria status cells recalculate. Mark reviews the register in week 4 of every month (05_Operating_Processes.docx section 7) and at the Day 90 and Month 12 gates; Lucy decides on any trigger that fires.
A6: Readers | B6: Lucy (decides), Mark (keeps the register and the gate review), 세무사 (Korea filings and structure rows), US CPA (US tax and treaty rows), attorney (IP and ownership rows), customs broker (tariff and classification rows).
A7: Probability scale (1 to 5) | B7: 1 = under 10% chance in the next 12 months. 2 = 10% to 25%. 3 = 25% to 50%. 4 = 50% to 75%. 5 = above 75%. Management estimates in every row; revisit at each gate.
A8: Impact scale (1 to 5) | B8: 1 = under $5,000 or a few days of delay. 2 = $5,000 to $25,000 or a month of delay. 3 = $25,000 to $100,000, about the size of the Medium funding gap ($116K), or a lost month of sales. 4 = $100,000 to $300,000, a lost quarter, or a filing penalty with account consequences. 5 = ends the Amazon plan, the funding plan or the legal structure. Management estimates; the dollar anchors come from the model.
A9: Score | B9: Score = Probability times Impact (live formula, 1 to 25). Red 15 to 25 = act now, named owner reports monthly. Amber 10 to 14 = watch, mitigation in place. Green 1 to 9 = accept and monitor. Rank breaks ties by register order.
A10: Kill criterion | B10: Yes means the risk maps to a kill trigger in the Day 90 or Month 12 gate (Kill Criteria tab). No further capital, sell down inventory, delist losers, move to Plan B.
A11: Basis | B11: Evidence based = the risk fact and its numbers come from the brief, the August model, a verified regulatory fact or the recalculated model. Management estimate = the build team's assumption, to be confirmed by the named owner. The probability and impact scores are management estimates in every row.
A12: Model context (Medium case) | B12: 18 month revenue $1.17M, net $153K (13.1%), cumulative breakeven Month 8. Year 5 revenue $4.58M, net $613K. Peak cash need $96K in Month 12; funding gap $116K needed by Month 2. Low case: 18 month net ($20K), Year 5 revenue $0.77M, Month 12 gate KILL.
A13: Legend | B13: Yellow fill with blue text = cell you edit. Black = fixed text or formula. Green = pulled from another sheet. [PLACEHOLDER: ...] = a fact that does not exist yet; never a guess.
A14: Hard stops that sit above this register | B14: No capital transfer before the ODI report is accepted. No PO before the HDMI Adopter certificate, ATC report and FCC report are on file. No in wall claim before the CL3 documentation. No HDMI version number on any box or promotion. Funding line committed before Month 2.
A16: Glossary
A17: AOC | B17: active optical cable
A18: HDMI | B18: High Definition Multimedia Interface
A19: HDMI LA | B19: HDMI Licensing Administrator
A20: ATC | B20: HDMI Authorized Test Center
A21: ASP | B21: average selling price
A22: COGS | B22: cost of goods sold
A23: FOB | B23: free on board (the price at the factory's port)
A24: FBA | B24: Fulfillment by Amazon
A25: FNSKU | B25: Fulfillment Network Stock Keeping Unit (Amazon's barcode)
A26: ASIN | B26: Amazon Standard Identification Number
A27: ACOS | B27: advertising cost of sales (ad spend divided by ad attributed sales)
A28: TACOS | B28: total advertising cost of sales (ad spend divided by total sales)
... A57: FX | B57: foreign exchange rate (KRW per USD)

Sheet Risk Register
A1: Risk register: BRAND LLC US launch (Lucy, Hyejin Yoo, 100% owner; H2 Company, Seoul)
A2: Edit the yellow cells only (Probability, Impact, Kill criterion). Score = Probability times Impact. Red 15 to 25, amber 10 to 14, green 1 to 9. Spare rows below the last risk take new entries; the counts and the Heat Map include them. Built October 8, 2026.
B3: Summary (live counts over the register)
B4: Risks | C4: Red (15 to 25) | D4: Amber (10 to 14) | E4: Green (1 to 9) | F4: Kill = Yes | G4: Average score | H4: Highest score
B5: =COUNTA($A$9:$A$60) -> 32 | C5: =COUNTIF($F$9:$F$60,">=15") -> 2 | D5: =COUNTIFS($F$9:$F$60,">=10",$F$9:$F$60,"<15") -> 11 | E5: =COUNTIFS($F$9:$F$60,">=1",$F$9:$F$60,"<10") -> 19 | F5: =COUNTIF($K$9:$K$60,"Yes") -> 9 | G5: =IF(B5=0,0,AVERAGE($F$9:$F$60)) -> 9.5 | H5: =MAX($F$9:$F$60) -> 20
B6: Check: band counts add up to the risk count (0 = ok) | C6: =B5-SUM(C5:E5) -> 0
A8: ID | B8: Risk | C8: Category | D8: Probability (1 to 5) | E8: Impact (1 to 5) | F8: Score | G8: Early warning signal | H8: Mitigation | I8: Owner | J8: Trigger for action | K8: Kill criterion (Yes or No) | L8: Basis | M8: Rank
A9: R01 | B9: Pending second Section 301 action adds 10 points of duty on China origin goods (stress case 50.1% against the copper base 40.1%) | C9: Tariff and customs | D9: 4 | E9: 3 | F9: =D9*E9 -> 12 | G9: USTR publishes a determination or a Federal Register notice on the investigation opened in March 2026; broker alert | H9: Stress case is already modeled: Medium 18 month net falls from $153K to $134K, Year 5 net from $613K to $534K (full model recalc at the stress rate). Hold the price ladder test (lever 10) in reserve, push the fiber ruling (lever 1), buy no more than the 2.5 month cover before a rate change date, and ask the broker about an earlier entry date for goods already on the water | I9: Broker, Mark | J9: Notice published with an effective date: rerun the model with DutyScenario 3 the same week and reprice within 30 days | K9: No | L9: Evidence based | M9: =IF(F9="","",RANK(F9,$F$9:$F$60)+COUNTIF($F$9:F9,F9)-1) -> 3
A10: R02 | B10: CBP binding ruling keeps the copper classification 8544.42.90 (40.1%) or the fiber heading also sits on List 3 (37.5% check row), so the 38% to 33.6% landed lever never arrives | C10: Tariff and customs | D10: 3 | E10: 3 | F10: =D10*E10 -> 9 | G10: Ruling letter received with 8544.42; broker reports that 8544.70.00 is covered by List 3 | H10: The base case already carries the copper rate, so the downside is a lost upside of $53K over 18 months (lever 1). File the ruling in week 1 with the factory's construction drawings showing the fiber data path; keep the landed cost at 38% in every plan until the letter arrives | I10: Broker, Mark | J10: Ruling letter received: update DutyScenario on Assumptions and the Levers tab the same day | K10: No | L10: Evidence based | M10: =IF(F10="","",RANK(F10,$F$9:$F$60)+COUNTIF($F$9:F10,F10)-1) -> 14
A11: R03 | B11: Factory cost gap: the Alibaba benchmark for a comparable 30 ft AOC is $17 to $22 FOB against the H2 base of $7.38 FOB for the hero; at the benchmark the hero loses ($1.61) to ($8.61) per unit at $44.99 and Medium 18 month net turns to ($287K) | C11: Product and compliance | D11: 3 | E11: 5 | F11: =D11*E11 -> 15 | G11: First USD quote from the factory for the LLC (not the Korea wholesale price) comes in above the H2 base; MOQ or payment terms differ from the Korea deal | H11: Get the factory's written USD FOB quote for the five launch SKUs before the LLC is formed. The single largest unverified assumption in the plan: if the quote is more than 25% above the H2 base, rerun SKU Unit Economics and reprice or stop before the first PO | I11: Lucy | J11: Written factory quote in USD above the H2 base: rerun the model before any PO; above the Alibaba low benchmark: stop and renegotiate or switch factory | K11: Yes | L11: Evidence based | M11: =IF(F11="","",RANK(F11,$F$9:$F$60)+COUNTIF($F$9:F11,F11)-1) -> 2
A12: R04 | B12: HDMI licensing: the factory is not an HDMI Adopter or has no ATC test report for the shipped construction, and HDMI LA seizes goods or forces a listing removal | C12: Product and compliance | D12: 2 | E12: 5 | F12: =D12*E12 -> 10 | G12: Factory cannot show the adopter certificate or the ATC report number within 10 days of the request; HDMI LA letter; Amazon compliance request | H12: No PO before the HDMI Adopter certificate [PLACEHOLDER: certificate number from factory] and the ATC report [PLACEHOLDER: report numbers] are on file. Packaging and promotion use the category name (Ultra High Speed HDMI Cable), never a version number. Titles may say 48Gbps and 8K | I12: Lucy, factory | J12: Any HDMI LA contact or a missing certificate at the PO date: hold the PO and the listing until the evidence is on file | K12: Yes | L12: Evidence based | M12: =IF(F12="","",RANK(F12,$F$9:$F$60)+COUNTIF($F$9:F12,F12)-1) -> 11
A13: R05 | B13: Amazon account suspension or failed identity verification (legal name mismatch across state, IRS, bank and Seller Central; account health drop; related account flag) | C13: Amazon account | D13: 2 | E13: 5 | F13: =D13*E13 -> 10 | G13: Verification request for more documents; account health score drops below Healthy; Seller Performance notice; payouts held | H13: Exact legal name match before any registration; Lucy as the beneficial owner on the account; VA checks account health every day; appeal pack template ready (invoices in the LLC's name, certificates). A suspension longer than 14 days in the gate window is a Day 90 kill trigger | I13: Mark, VA | J13: Any performance notification: Mark answers within 48 hours; suspension open more than 14 days: gate review | K13: Yes | L13: Evidence based | M13: =IF(F13="","",RANK(F13,$F$9:$F$60)+COUNTIF($F$9:F13,F13)-1) -> 12
A14: R06 | B14: Intellectual property complaint against the listing (trademark, HDMI logo use, utility or design patent claim on the connector) that Amazon treats as a rights owner complaint | C14: Amazon account | D14: 2 | E14: 4 | F14: =D14*E14 -> 8 | G14: Rights owner notice in Seller Central; listing goes down for a single ASIN; competitor files a report | H14: Brand Registry on a pending application (Amazon Brand Registry accepts a pending application); logo use confirmed in writing by the factory under its license terms; no competitor brand names in backend keywords; attorney on call for a counter notice. A complaint open more than 14 days is a Day 90 kill trigger | I14: Mark, attorney | J14: Complaint received: attorney response within 5 business days; open more than 14 days: gate review | K14: Yes | L14: Evidence based | M14: =IF(F14="","",RANK(F14,$F$9:$F$60)+COUNTIF($F$9:F14,F14)-1) -> 20
A15: R07 | B15: Working capital runs out before the ramp pays back: Medium peak cash need $96K in Month 12 against $39K opening capital, funding gap $116K needed by Month 2; Low peak $114K in Month 24 | C15: Cash and FX | D15: 4 | E15: 5 | F15: =D15*E15 -> 20 | G15: Cash balance tracks below the model's monthly line; next PO deposit cannot be paid without delaying it; runway at the Day 90 gate below 4 months | H15: Commit the funding line (retained earnings first, then the line of credit or investor amount) before Month 2, not when the balance turns negative. Hold inventory cover at 2.5 months, order in smaller lots during the ramp, and run the monthly cash check in the close. Runway below 2 months is a Day 90 kill trigger | I15: Lucy, Mark | J15: Cash balance more than 10% below the model line for two months, or runway below 4 months: stop the next PO until funding is in place | K15: Yes | L15: Evidence based | M15: =IF(F15="","",RANK(F15,$F$9:$F$60)+COUNTIF($F$9:F15,F15)-1) -> 1
A16: R08 | B16: FX: a stronger won raises the USD cost of KRW priced goods; at 1,300 KRW per USD Medium 18 month net is $134K against $153K at 1,430 (1,550 gives $168K) | C16: Cash and FX | D16: 3 | E16: 2 | F16: =D16*E16 -> 6 | G16: KRW per USD moves below 1,350 for a month; factory invoices in KRW rather than USD | H16: Ask the factory for a USD quote, which removes the effect from the cost side; keep capital in USD once transferred; FX is an input cell (FXRate) so the model reprices in minutes | I16: Lucy | J16: Rate below 1,350 at a PO date: rerun the model at the spot rate before signing the PO | K16: No | L16: Evidence based | M16: =IF(F16="","",RANK(F16,$F$9:$F$60)+COUNTIF($F$9:F16,F16)-1) -> 26
A17: R09 | B17: Return rate above plan: Medium carries 3%, Low 4%; at 5% Medium 18 month net falls to $130K; above 7% at Day 90 is a kill trigger | C17: Product and compliance | D17: 3 | E17: 3 | F17: =D17*E17 -> 9 | G17: Return reasons show wrong direction, no signal or defective; return rate above 4% in any month; negative reviews mention no picture | H17: Direction proof design (color coded SOURCE and DISPLAY ends, printed arrows, QR setup video) is lever 3 (3% to 2%); FAQ in the listing on directionality and in wall installs; 5 Year Signal Guarantee with the replacement shipped before the return arrives keeps the review clean; third party QC before departure | I17: Lucy, factory | J17: Return rate above 4% for two months: pull the return reasons and change the insert card or packaging within 30 days | K17: Yes | L17: Evidence based | M17: =IF(F17="","",RANK(F17,$F$9:$F$60)+COUNTIF($F$9:F17,F17)-1) -> 15
A18: R10 | B18: Counterfeits and listing hijackers sell on the ASIN at a lower price, take the buy box and generate bad reviews on the brand | C18: Amazon account | D18: 3 | E18: 3 | F18: =D18*E18 -> 9 | G18: A second seller appears on the ASIN; buy box share drops; reviews mention a different box or no guarantee card | H18: Brand Registry (hijacker protection) on the pending application; Transparency codes or a serialized guarantee card [PLACEHOLDER: program fee]; test buy and report through Brand Registry; keep the FNSKU labels applied at the factory | I18: Mark | J18: Any unauthorized seller on a BRAND ASIN: test buy and report within 7 days | K18: No | L18: Management estimate | M18: =IF(F18="","",RANK(F18,$F$9:$F$60)+COUNTIF($F$9:F18,F18)-1) -> 16
A19: R11 | B19: Amazon fee changes: referral, FBA fulfillment, storage, inbound placement or the Professional fee rise faster than the 3% per year FBA inflation in the model | C19: Amazon account | D19: 4 | E19: 2 | F19: =D19*E19 -> 8 | G19: Amazon fee change notice (usually announced for the next calendar year); FBA fee preview shows a higher size tier | H19: Model carries 3% FBA inflation per year from Year 2; packaging to a smaller size tier (lever 8, $5.50 to $4.75 on 7M and 10M); 3PL feeding FBA to avoid aged inventory surcharges (lever 9); reprice through the list and sale price ladder (lever 10) | I19: Mark | J19: Fee notice received: update the SKU Unit Economics tab within 14 days and reprice if net per unit on the hero falls below $11 before advertising | K19: No | L19: Management estimate | M19: =IF(F19="","",RANK(F19,$F$9:$F$60)+COUNTIF($F$9:F19,F19)-1) -> 21
A20: R12 | B20: Key person: Lucy (100% owner) is the only signer for the LLC, the bank, the factory and the Korean filings; illness or absence stops payments and filings | C20: People | D20: 2 | E20: 5 | F20: =D20*E20 -> 10 | G20: Payment or filing deadlines slip; Lucy unreachable for more than 5 business days during the launch window | H20: Operating agreement names a successor or a limited power of attorney for payments [PLACEHOLDER: attorney wording]; bank user with view and payment approval limits; shared password manager; compliance calendar visible to Mark. Any grant of authority to Mark must keep the treaty position (no contract signing on the LLC's behalf) | I20: Lucy, attorney | J20: Lucy unavailable for more than 5 business days: Mark runs the compliance calendar and defers POs | K20: No | L20: Management estimate | M20: =IF(F20="","",RANK(F20,$F$9:$F$60)+COUNTIF($F$9:F20,F20)-1) -> 13
... A40: R32 | B40: H2 Company structure: H2 is a Korean sole proprietorship (registration number 599-64-00496, middle digits 64), so Lucy invests personally; the 세무사 may advise incorporating H2 first, which changes the investor, the reports and the Korean tax on the LLC's profit | C40: Legal, tax and structure | D40: 3 | E40: 2 | F40: =D40*E40 -> 6 | G40: 세무사 advice pending past week 2; bank questions who the investor is | H40: Ask the 세무사 the incorporate H2 first question in week 1 and record the answer in 11_Decision_Log.md; the ODI report is filed by whichever entity the answer names; the model assumes Lucy owns 100% personally | I40: Lucy, 세무사 | J40: Advice to incorporate first: pause the capital transfer, incorporate, then file the ODI report | K40: No | L40: Management estimate | M40: =IF(F40="","",RANK(F40,$F$9:$F$60)+COUNTIF($F$9:F40,F40)-1) -> 31
F41: =IF(OR(D41="",E41=""),"",D41*E41) | M41: =IF(F41="","",RANK(F41,$F$9:$F$60)+COUNTIF($F$9:F41,F41)-1)
F42: =IF(OR(D42="",E42=""),"",D42*E42) | M42: =IF(F42="","",RANK(F42,$F$9:$F$60)+COUNTIF($F$9:F42,F42)-1)
F43: =IF(OR(D43="",E43=""),"",D43*E43) | M43: =IF(F43="","",RANK(F43,$F$9:$F$60)+COUNTIF($F$9:F43,F43)-1)
F44: =IF(OR(D44="",E44=""),"",D44*E44) | M44: =IF(F44="","",RANK(F44,$F$9:$F$60)+COUNTIF($F$9:F44,F44)-1)
F45: =IF(OR(D45="",E45=""),"",D45*E45) | M45: =IF(F45="","",RANK(F45,$F$9:$F$60)+COUNTIF($F$9:F45,F45)-1)
F46: =IF(OR(D46="",E46=""),"",D46*E46) | M46: =IF(F46="","",RANK(F46,$F$9:$F$60)+COUNTIF($F$9:F46,F46)-1)
F47: =IF(OR(D47="",E47=""),"",D47*E47) | M47: =IF(F47="","",RANK(F47,$F$9:$F$60)+COUNTIF($F$9:F47,F47)-1)
F48: =IF(OR(D48="",E48=""),"",D48*E48) | M48: =IF(F48="","",RANK(F48,$F$9:$F$60)+COUNTIF($F$9:F48,F48)-1)
F49: =IF(OR(D49="",E49=""),"",D49*E49) | M49: =IF(F49="","",RANK(F49,$F$9:$F$60)+COUNTIF($F$9:F49,F49)-1)
F50: =IF(OR(D50="",E50=""),"",D50*E50) | M50: =IF(F50="","",RANK(F50,$F$9:$F$60)+COUNTIF($F$9:F50,F50)-1)
F51: =IF(OR(D51="",E51=""),"",D51*E51) | M51: =IF(F51="","",RANK(F51,$F$9:$F$60)+COUNTIF($F$9:F51,F51)-1)
F52: =IF(OR(D52="",E52=""),"",D52*E52) | M52: =IF(F52="","",RANK(F52,$F$9:$F$60)+COUNTIF($F$9:F52,F52)-1)
... F60: =IF(OR(D60="",E60=""),"",D60*E60) | M60: =IF(F60="","",RANK(F60,$F$9:$F$60)+COUNTIF($F$9:F60,F60)-1)
A61: End of list. Add new risks in the spare rows above this line so the summary and the Heat Map count them.

Sheet Kill Criteria
A1: Kill criteria: Day 90 gate (end of Month 3) and Month 12 gate, with the model values beside each threshold
A2: Thresholds and model values come from build/figures.json (gate_thresholds and scenarios.*.gates). KILL if any kill trigger fires; PASS if every modeled pass threshold is met; REVIEW otherwise. Kill means: No further capital, sell down inventory, delist losers, move to Plan B. Observed metrics (conversion, suppressed listing, IP complaint) are read from Seller Central at the gate; the status cells here cover the modeled metrics only.
A4: Gate thresholds (numbers; the status formulas read these cells)
A5: Threshold | B5: Value | C5: Unit
A6: Day 90: unit session conversion, pass at or above (3 of 5 launch SKUs; observed) | B6: 0.08 | C6: percent
A7: Day 90: hero conversion, kill below (observed) | B7: 0.05 | C7: percent
A8: Day 90: TACOS in Month 3, pass at or below | B8: 0.3 | C8: percent
A9: Day 90: TACOS in Month 3, kill above | B9: 0.4 | C9: percent
A10: Day 90: return rate, pass at or below | B10: 0.04 | C10: percent
A11: Day 90: return rate, kill above | B11: 0.07 | C11: percent
A12: Day 90: contribution per unit before advertising, pass at or above | B12: 11 | C12: USD
A13: Day 90: hero contribution per unit before advertising, kill below | B13: 8 | C13: USD
A14: Day 90: cash runway after funding, months, pass at or above | B14: 4 | C14: months
A15: Day 90: cash runway, months, kill below | B15: 2 | C15: months
A16: Day 90: suppressed listing or IP complaint open more than this many days is a kill (observed) | B16: 14 | C16: days
A17: Month 12: monthly revenue, pass at or above | B17: 70000 | C17: USD
... A25: Month 12: funding gap above this with three negative operating cash flow months is a kill | B25: 50000 | C25: USD
A27: Scenario context from the model
A28: Item | E28: Low | G28: Medium | I28: High | K28: Note
A29: Funding gap (1.2 times the negative minimum cash balance) | E29: 136483.45 | G29: 115583.03 | I29: 40918.303 | K29: Read by the Month 12 operating cash flow status formula
A30: Funding needed by | E30: 2 | G30: 2 | I30: 1 | K30: The month before the balance first goes negative
A31: Peak cash need | E31: 113736.21 | G31: 96319.189 | I31: 34098.586
A32: Peak cash need month | E32: 24 | G32: 12 | I32: 7
A33: Cash runway at the Day 90 gate after funding, months | E33: 15.261247 | G33: 10.20197 | I33: 4.0398372 | K33: Cash at the end of Month 3 after the funding line, divided by the average operating burn of Months 4 to 6
A34: 18 month net (Amazon US) | E34: -19636.1 | G34: 153020.18 | I34: 447155.24
A35: Cumulative breakeven month | E35: none | G35: 8 | I35: 5 | K35: none = no cumulative breakeven in 18 months
A36: Month 12 revenue | E36: 46740 | G36: 86100 | I36: 136654
A37: Year 5 revenue | E37: 768330.22 | G37: 4576228.4 | I37: 8296603.8
A38: Year 5 net | E38: -2460.9059 | G38: 612714.57 | I38: 1838289.8
A40: Day 90 gate (end of Month 3). Pass requires every row; any kill trigger stops further capital
A41: Metric | B41: Pass threshold | C41: Kill trigger | D41: Source | E41: Low model value | F41: Low status | G41: Medium model value | H41: Medium status | I41: High model value | J41: High status | K41: Note
A42: Unit session conversion on at least 3 of the 5 launch SKUs | B42: at or above 8% | C42: hero below 5% | D42: observed | E42: [PLACEHOLDER: observed at the gate] | F42: observed | G42: [PLACEHOLDER: observed at the gate] | H42: observed | I42: [PLACEHOLDER: observed at the gate] | J42: observed | K42: Observed in Seller Central (unit session percentage per child ASIN).
A43: TACOS in Month 3, falling month over month | B43: at or below 30% | C43: above 40% | D43: model | E43: 0.37 | F43: =IF(E43>$B$9,"KILL",IF(E43<=$B$8,"PASS","REVIEW")) -> REVIEW | G43: 0.3 | H43: =IF(G43>$B$9,"KILL",IF(G43<=$B$8,"PASS","REVIEW")) -> PASS | I43: 0.26 | J43: =IF(I43>$B$9,"KILL",IF(I43<=$B$8,"PASS","REVIEW")) -> PASS | K43: Model value is the Month 3 ad spend rate. The falling month over month test is observed.
A44: Return rate | B44: at or below 4% | C44: above 7% | D44: model | E44: 0.04 | F44: =IF(E44>$B$11,"KILL",IF(E44<=$B$10,"PASS","REVIEW")) -> PASS | G44: 0.03 | H44: =IF(G44>$B$11,"KILL",IF(G44<=$B$10,"PASS","REVIEW")) -> PASS | I44: 0.025 | J44: =IF(I44>$B$11,"KILL",IF(I44<=$B$10,"PASS","REVIEW")) -> PASS | K44: Model value is the scenario return rate in Month 3.
A45: Contribution per unit before advertising on at least 3 of 5 SKUs | B45: at or above $11 (Medium hero $12.14) | C45: hero below $8 | D45: model | E45: 8.18 | F45: =IF(E45<$B$13,"KILL",IF(E45>=$B$12,"PASS","REVIEW")) -> REVIEW | G45: 12.14 | H45: =IF(G45<$B$13,"KILL",IF(G45>=$B$12,"PASS","REVIEW")) -> PASS | I45: 15.355 | J45: =IF(I45<$B$13,"KILL",IF(I45>=$B$12,"PASS","REVIEW")) -> PASS | K45: Model value is the hero contribution per unit before advertising at the scenario ASP; the 3 of 5 SKU test is observed.
A46: Cash runway after funding the next purchase order | B46: at or above 4 months | C46: below 2 months | D46: model | E46: 15.261247 | F46: =IF(E46<$B$15,"KILL",IF(E46>=$B$14,"PASS","REVIEW")) -> PASS | G46: 10.20197 | H46: =IF(G46<$B$15,"KILL",IF(G46>=$B$14,"PASS","REVIEW")) -> PASS | I46: 4.0398372 | J46: =IF(I46<$B$15,"KILL",IF(I46>=$B$14,"PASS","REVIEW")) -> PASS | K46: Model value assumes the funding line is in place by the month shown in the context block.
A47: Suppressed listing or IP complaint | B47: none open | C47: any open more than 14 days | D47: observed | E47: [PLACEHOLDER: observed at the gate] | F47: observed | G47: [PLACEHOLDER: observed at the gate] | H47: observed | I47: [PLACEHOLDER: observed at the gate] | J47: observed | K47: Observed: any suppression or IP complaint open more than 14 days is a kill.
A48: Gate result from the status cells above (modeled metrics only) | F48: =IF(COUNTIF(F42:F47,"KILL")>0,"KILL",IF(COUNTIF(F42:F47,"REVIEW")>0,"REVIEW","PASS")) -> REVIEW | H48: =IF(COUNTIF(H42:H47,"KILL")>0,"KILL",IF(COUNTIF(H42:H47,"REVIEW")>0,"REVIEW","PASS")) -> PASS | J48: =IF(COUNTIF(J42:J47,"KILL")>0,"KILL",IF(COUNTIF(J42:J47,"REVIEW")>0,"REVIEW","PASS")) -> PASS
A49: Gate result in the model (figures.json) | F49: REVIEW | H49: PASS | J49: PASS
A50: Check: formula result equals the model result (0 = ok) | F50: =IF(F48=F49,0,1) -> 0 | H50: =IF(H48=H49,0,1) -> 0 | J50: =IF(J48=J49,0,1) -> 0
...

Sheet Heat Map
A1: Heat map: count of risks by probability and impact (COUNTIFS over the Risk Register tab, spare rows included)
A2: Rows are probability (5 at the top), columns are impact. Cell color is the score band of that cell (red 15 to 25, amber 10 to 14, green 1 to 9). Bold = at least one risk in the cell.
A4: Probability \ Impact | B4: Impact 1 | C4: Impact 2 | D4: Impact 3 | E4: Impact 4 | F4: Impact 5 | G4: Total
A5: Probability 5 | B5: =COUNTIFS('Risk Register'!$D$9:$D$60,5,'Risk Register'!$E$9:$E$60,1) -> 0 | C5: =COUNTIFS('Risk Register'!$D$9:$D$60,5,'Risk Register'!$E$9:$E$60,2) -> 0 | D5: =COUNTIFS('Risk Register'!$D$9:$D$60,5,'Risk Register'!$E$9:$E$60,3) -> 0 | E5: =COUNTIFS('Risk Register'!$D$9:$D$60,5,'Risk Register'!$E$9:$E$60,4) -> 0 | F5: =COUNTIFS('Risk Register'!$D$9:$D$60,5,'Risk Register'!$E$9:$E$60,5) -> 0 | G5: =SUM(B5:F5) -> 0
A6: Probability 4 | B6: =COUNTIFS('Risk Register'!$D$9:$D$60,4,'Risk Register'!$E$9:$E$60,1) -> 0 | C6: =COUNTIFS('Risk Register'!$D$9:$D$60,4,'Risk Register'!$E$9:$E$60,2) -> 1 | D6: =COUNTIFS('Risk Register'!$D$9:$D$60,4,'Risk Register'!$E$9:$E$60,3) -> 2 | E6: =COUNTIFS('Risk Register'!$D$9:$D$60,4,'Risk Register'!$E$9:$E$60,4) -> 0 | F6: =COUNTIFS('Risk Register'!$D$9:$D$60,4,'Risk Register'!$E$9:$E$60,5) -> 1 | G6: =SUM(B6:F6) -> 4
A7: Probability 3 | B7: =COUNTIFS('Risk Register'!$D$9:$D$60,3,'Risk Register'!$E$9:$E$60,1) -> 0 | C7: =COUNTIFS('Risk Register'!$D$9:$D$60,3,'Risk Register'!$E$9:$E$60,2) -> 4 | D7: =COUNTIFS('Risk Register'!$D$9:$D$60,3,'Risk Register'!$E$9:$E$60,3) -> 6 | E7: =COUNTIFS('Risk Register'!$D$9:$D$60,3,'Risk Register'!$E$9:$E$60,4) -> 6 | F7: =COUNTIFS('Risk Register'!$D$9:$D$60,3,'Risk Register'!$E$9:$E$60,5) -> 1 | G7: =SUM(B7:F7) -> 17
A8: Probability 2 | B8: =COUNTIFS('Risk Register'!$D$9:$D$60,2,'Risk Register'!$E$9:$E$60,1) -> 0 | C8: =COUNTIFS('Risk Register'!$D$9:$D$60,2,'Risk Register'!$E$9:$E$60,2) -> 0 | D8: =COUNTIFS('Risk Register'!$D$9:$D$60,2,'Risk Register'!$E$9:$E$60,3) -> 2 | E8: =COUNTIFS('Risk Register'!$D$9:$D$60,2,'Risk Register'!$E$9:$E$60,4) -> 5 | F8: =COUNTIFS('Risk Register'!$D$9:$D$60,2,'Risk Register'!$E$9:$E$60,5) -> 3 | G8: =SUM(B8:F8) -> 10
A9: Probability 1 | B9: =COUNTIFS('Risk Register'!$D$9:$D$60,1,'Risk Register'!$E$9:$E$60,1) -> 0 | C9: =COUNTIFS('Risk Register'!$D$9:$D$60,1,'Risk Register'!$E$9:$E$60,2) -> 0 | D9: =COUNTIFS('Risk Register'!$D$9:$D$60,1,'Risk Register'!$E$9:$E$60,3) -> 0 | E9: =COUNTIFS('Risk Register'!$D$9:$D$60,1,'Risk Register'!$E$9:$E$60,4) -> 0 | F9: =COUNTIFS('Risk Register'!$D$9:$D$60,1,'Risk Register'!$E$9:$E$60,5) -> 1 | G9: =SUM(B9:F9) -> 1
A10: Total | B10: =SUM(B5:B9) -> 0 | C10: =SUM(C5:C9) -> 5 | D10: =SUM(D5:D9) -> 10 | E10: =SUM(E5:E9) -> 11 | F10: =SUM(F5:F9) -> 6 | G10: =SUM(G5:G9) -> 32
A11: Check (0 = ok) | B11: =G10-'Risk Register'!B5 -> 0
A13: Risks tied to a kill trigger (Kill criterion = Yes), same grid
A14: Probability \ Impact | B14: Impact 1 | C14: Impact 2 | D14: Impact 3 | E14: Impact 4 | F14: Impact 5 | G14: Total
A15: Probability 5 | B15: =COUNTIFS('Risk Register'!$D$9:$D$60,5,'Risk Register'!$E$9:$E$60,1,'Risk Register'!$K$9:$K$60,"Yes") -> 0 | C15: =COUNTIFS('Risk Register'!$D$9:$D$60,5,'Risk Register'!$E$9:$E$60,2,'Risk Register'!$K$9:$K$60,"Yes") -> 0 | D15: =COUNTIFS('Risk Register'!$D$9:$D$60,5,'Risk Register'!$E$9:$E$60,3,'Risk Register'!$K$9:$K$60,"Yes") -> 0 | E15: =COUNTIFS('Risk Register'!$D$9:$D$60,5,'Risk Register'!$E$9:$E$60,4,'Risk Register'!$K$9:$K$60,"Yes") -> 0 | F15: =COUNTIFS('Risk Register'!$D$9:$D$60,5,'Risk Register'!$E$9:$E$60,5,'Risk Register'!$K$9:$K$60,"Yes") -> 0 | G15: =SUM(B15:F15) -> 0
A16: Probability 4 | B16: =COUNTIFS('Risk Register'!$D$9:$D$60,4,'Risk Register'!$E$9:$E$60,1,'Risk Register'!$K$9:$K$60,"Yes") -> 0 | C16: =COUNTIFS('Risk Register'!$D$9:$D$60,4,'Risk Register'!$E$9:$E$60,2,'Risk Register'!$K$9:$K$60,"Yes") -> 0 | D16: =COUNTIFS('Risk Register'!$D$9:$D$60,4,'Risk Register'!$E$9:$E$60,3,'Risk Register'!$K$9:$K$60,"Yes") -> 0 | E16: =COUNTIFS('Risk Register'!$D$9:$D$60,4,'Risk Register'!$E$9:$E$60,4,'Risk Register'!$K$9:$K$60,"Yes") -> 0 | F16: =COUNTIFS('Risk Register'!$D$9:$D$60,4,'Risk Register'!$E$9:$E$60,5,'Risk Register'!$K$9:$K$60,"Yes") -> 1 | G16: =SUM(B16:F16) -> 1
A17: Probability 3 | B17: =COUNTIFS('Risk Register'!$D$9:$D$60,3,'Risk Register'!$E$9:$E$60,1,'Risk Register'!$K$9:$K$60,"Yes") -> 0 | C17: =COUNTIFS('Risk Register'!$D$9:$D$60,3,'Risk Register'!$E$9:$E$60,2,'Risk Register'!$K$9:$K$60,"Yes") -> 0 | D17: =COUNTIFS('Risk Register'!$D$9:$D$60,3,'Risk Register'!$E$9:$E$60,3,'Risk Register'!$K$9:$K$60,"Yes") -> 2 | E17: =COUNTIFS('Risk Register'!$D$9:$D$60,3,'Risk Register'!$E$9:$E$60,4,'Risk Register'!$K$9:$K$60,"Yes") -> 2 | F17: =COUNTIFS('Risk Register'!$D$9:$D$60,3,'Risk Register'!$E$9:$E$60,5,'Risk Register'!$K$9:$K$60,"Yes") -> 1 | G17: =SUM(B17:F17) -> 5
A18: Probability 2 | B18: =COUNTIFS('Risk Register'!$D$9:$D$60,2,'Risk Register'!$E$9:$E$60,1,'Risk Register'!$K$9:$K$60,"Yes") -> 0 | C18: =COUNTIFS('Risk Register'!$D$9:$D$60,2,'Risk Register'!$E$9:$E$60,2,'Risk Register'!$K$9:$K$60,"Yes") -> 0 | D18: =COUNTIFS('Risk Register'!$D$9:$D$60,2,'Risk Register'!$E$9:$E$60,3,'Risk Register'!$K$9:$K$60,"Yes") -> 0 | E18: =COUNTIFS('Risk Register'!$D$9:$D$60,2,'Risk Register'!$E$9:$E$60,4,'Risk Register'!$K$9:$K$60,"Yes") -> 1 | F18: =COUNTIFS('Risk Register'!$D$9:$D$60,2,'Risk Register'!$E$9:$E$60,5,'Risk Register'!$K$9:$K$60,"Yes") -> 2 | G18: =SUM(B18:F18) -> 3
A19: Probability 1 | B19: =COUNTIFS('Risk Register'!$D$9:$D$60,1,'Risk Register'!$E$9:$E$60,1,'Risk Register'!$K$9:$K$60,"Yes") -> 0 | C19: =COUNTIFS('Risk Register'!$D$9:$D$60,1,'Risk Register'!$E$9:$E$60,2,'Risk Register'!$K$9:$K$60,"Yes") -> 0 | D19: =COUNTIFS('Risk Register'!$D$9:$D$60,1,'Risk Register'!$E$9:$E$60,3,'Risk Register'!$K$9:$K$60,"Yes") -> 0 | E19: =COUNTIFS('Risk Register'!$D$9:$D$60,1,'Risk Register'!$E$9:$E$60,4,'Risk Register'!$K$9:$K$60,"Yes") -> 0 | F19: =COUNTIFS('Risk Register'!$D$9:$D$60,1,'Risk Register'!$E$9:$E$60,5,'Risk Register'!$K$9:$K$60,"Yes") -> 0 | G19: =SUM(B19:F19) -> 0
A20: Total | B20: =SUM(B15:B19) -> 0 | C20: =SUM(C15:C19) -> 0 | D20: =SUM(D15:D19) -> 2 | E20: =SUM(E15:E19) -> 3 | F20: =SUM(F15:F19) -> 4 | G20: =SUM(G15:G19) -> 9
A22: By score band | B22: Risks | C22: Share | D22: Kill = Yes
A23: Red (15 to 25) | B23: =COUNTIF('Risk Register'!$F$9:$F$60,">=15") -> 2 | C23: =IF('Risk Register'!B5=0,0,B23/'Risk Register'!B5) -> 0.0625 | D23: =COUNTIFS('Risk Register'!$F$9:$F$60,">=15",'Risk Register'!$K$9:$K$60,"Yes") -> 2
A24: Amber (10 to 14) | B24: =COUNTIFS('Risk Register'!$F$9:$F$60,">=10",'Risk Register'!$F$9:$F$60,"<15") -> 11 | C24: =IF('Risk Register'!B5=0,0,B24/'Risk Register'!B5) -> 0.34375 | D24: =COUNTIFS('Risk Register'!$F$9:$F$60,">=10",'Risk Register'!$F$9:$F$60,"<15",'Risk Register'!$K$9:$K$60,"Yes") -> 4
A25: Green (1 to 9) | B25: =COUNTIFS('Risk Register'!$F$9:$F$60,">=1",'Risk Register'!$F$9:$F$60,"<10") -> 19 | C25: =IF('Risk Register'!B5=0,0,B25/'Risk Register'!B5) -> 0.59375 | D25: =COUNTIFS('Risk Register'!$F$9:$F$60,">=1",'Risk Register'!$F$9:$F$60,"<10",'Risk Register'!$K$9:$K$60,"Yes") -> 3
A27: By category | B27: Risks | C27: Average score | D27: Highest score | E27: Red | F27: Kill = Yes
A28: Tariff and customs | B28: =COUNTIF('Risk Register'!$C$9:$C$60,A28) -> 2 | C28: =IF(B28=0,0,SUMIFS('Risk Register'!$F$9:$F$60,'Risk Register'!$C$9:$C$60,A28)/B28) -> 10.5 | D28: =IF(B28=0,0,SUMPRODUCT(MAX(('Risk Register'!$C$9:$C$60=A28)*'Risk Register'!$D$9:$D$60*'Risk Register'!$E$9:$E$60))) -> 12 | E28: =COUNTIFS('Risk Register'!$C$9:$C$60,A28,'Risk Register'!$F$9:$F$60,">=15") -> 0 | F28: =COUNTIFS('Risk Register'!$C$9:$C$60,A28,'Risk Register'!$K$9:$K$60,"Yes") -> 0
A29: Product and compliance | B29: =COUNTIF('Risk Register'!$C$9:$C$60,A29) -> 5 | C29: =IF(B29=0,0,SUMIFS('Risk Register'!$F$9:$F$60,'Risk Register'!$C$9:$C$60,A29)/B29) -> 10.2 | D29: =IF(B29=0,0,SUMPRODUCT(MAX(('Risk Register'!$C$9:$C$60=A29)*'Risk Register'!$D$9:$D$60*'Risk Register'!$E$9:$E$60))) -> 15 | E29: =COUNTIFS('Risk Register'!$C$9:$C$60,A29,'Risk Register'!$F$9:$F$60,">=15") -> 1 | F29: =COUNTIFS('Risk Register'!$C$9:$C$60,A29,'Risk Register'!$K$9:$K$60,"Yes") -> 3
A30: Amazon account | B30: =COUNTIF('Risk Register'!$C$9:$C$60,A30) -> 6 | C30: =IF(B30=0,0,SUMIFS('Risk Register'!$F$9:$F$60,'Risk Register'!$C$9:$C$60,A30)/B30) -> 9.1666667 | D30: =IF(B30=0,0,SUMPRODUCT(MAX(('Risk Register'!$C$9:$C$60=A30)*'Risk Register'!$D$9:$D$60*'Risk Register'!$E$9:$E$60))) -> 12 | E30: =COUNTIFS('Risk Register'!$C$9:$C$60,A30,'Risk Register'!$F$9:$F$60,">=15") -> 0 | F30: =COUNTIFS('Risk Register'!$C$9:$C$60,A30,'Risk Register'!$K$9:$K$60,"Yes") -> 3
A31: Cash and FX | B31: =COUNTIF('Risk Register'!$C$9:$C$60,A31) -> 3 | C31: =IF(B31=0,0,SUMIFS('Risk Register'!$F$9:$F$60,'Risk Register'!$C$9:$C$60,A31)/B31) -> 12.666667 | D31: =IF(B31=0,0,SUMPRODUCT(MAX(('Risk Register'!$C$9:$C$60=A31)*'Risk Register'!$D$9:$D$60*'Risk Register'!$E$9:$E$60))) -> 20 | E31: =COUNTIFS('Risk Register'!$C$9:$C$60,A31,'Risk Register'!$F$9:$F$60,">=15") -> 1 | F31: =COUNTIFS('Risk Register'!$C$9:$C$60,A31,'Risk Register'!$K$9:$K$60,"Yes") -> 1
A32: Supply chain and operations | B32: =COUNTIF('Risk Register'!$C$9:$C$60,A32) -> 5 | C32: =IF(B32=0,0,SUMIFS('Risk Register'!$F$9:$F$60,'Risk Register'!$C$9:$C$60,A32)/B32) -> 8.4 | D32: =IF(B32=0,0,SUMPRODUCT(MAX(('Risk Register'!$C$9:$C$60=A32)*'Risk Register'!$D$9:$D$60*'Risk Register'!$E$9:$E$60))) -> 12 | E32: =COUNTIFS('Risk Register'!$C$9:$C$60,A32,'Risk Register'!$F$9:$F$60,">=15") -> 0 | F32: =COUNTIFS('Risk Register'!$C$9:$C$60,A32,'Risk Register'!$K$9:$K$60,"Yes") -> 0
A33: Legal, tax and structure | B33: =COUNTIF('Risk Register'!$C$9:$C$60,A33) -> 6 | C33: =IF(B33=0,0,SUMIFS('Risk Register'!$F$9:$F$60,'Risk Register'!$C$9:$C$60,A33)/B33) -> 7.6666667 | D33: =IF(B33=0,0,SUMPRODUCT(MAX(('Risk Register'!$C$9:$C$60=A33)*'Risk Register'!$D$9:$D$60*'Risk Register'!$E$9:$E$60))) -> 12 | E33: =COUNTIFS('Risk Register'!$C$9:$C$60,A33,'Risk Register'!$F$9:$F$60,">=15") -> 0 | F33: =COUNTIFS('Risk Register'!$C$9:$C$60,A33,'Risk Register'!$K$9:$K$60,"Yes") -> 0
A34: Market and demand | B34: =COUNTIF('Risk Register'!$C$9:$C$60,A34) -> 3 | C34: =IF(B34=0,0,SUMIFS('Risk Register'!$F$9:$F$60,'Risk Register'!$C$9:$C$60,A34)/B34) -> 11 | D34: =IF(B34=0,0,SUMPRODUCT(MAX(('Risk Register'!$C$9:$C$60=A34)*'Risk Register'!$D$9:$D$60*'Risk Register'!$E$9:$E$60))) -> 12 | E34: =COUNTIFS('Risk Register'!$C$9:$C$60,A34,'Risk Register'!$F$9:$F$60,">=15") -> 0 | F34: =COUNTIFS('Risk Register'!$C$9:$C$60,A34,'Risk Register'!$K$9:$K$60,"Yes") -> 2
A35: People | B35: =COUNTIF('Risk Register'!$C$9:$C$60,A35) -> 2 | C35: =IF(B35=0,0,SUMIFS('Risk Register'!$F$9:$F$60,'Risk Register'!$C$9:$C$60,A35)/B35) -> 9 | D35: =IF(B35=0,0,SUMPRODUCT(MAX(('Risk Register'!$C$9:$C$60=A35)*'Risk Register'!$D$9:$D$60*'Risk Register'!$E$9:$E$60))) -> 10 | E35: =COUNTIFS('Risk Register'!$C$9:$C$60,A35,'Risk Register'!$F$9:$F$60,">=15") -> 0 | F35: =COUNTIFS('Risk Register'!$C$9:$C$60,A35,'Risk Register'!$K$9:$K$60,"Yes") -> 0
A36: Total | B36: =SUM(B28:B35) -> 32 | E36: =SUM(E28:E35) -> 2 | F36: =SUM(F28:F35) -> 9
A38: Top 8 risks by score (rank from the register; ties keep register order)
A39: Position | B39: Rank | C39: ID | D39: Score | E39: Probability | F39: Impact | G39: Kill = Yes | I39: Risk | J39: Owner
A40: Rank 1 | B40: 1 | C40: =IFERROR(INDEX('Risk Register'!$A$9:$A$60,MATCH(B40,'Risk Register'!$M$9:$M$60,0)),"") -> R07 | D40: =IFERROR(INDEX('Risk Register'!$F$9:$F$60,MATCH(B40,'Risk Register'!$M$9:$M$60,0)),"") -> 20 | E40: =IFERROR(INDEX('Risk Register'!$D$9:$D$60,MATCH(B40,'Risk Register'!$M$9:$M$60,0)),"") -> 4 | F40: =IFERROR(INDEX('Risk Register'!$E$9:$E$60,MATCH(B40,'Risk Register'!$M$9:$M$60,0)),"") -> 5 | G40: =IFERROR(INDEX('Risk Register'!$K$9:$K$60,MATCH(B40,'Risk Register'!$M$9:$M$60,0)),"") -> Yes | I40: =IFERROR(INDEX('Risk Register'!$B$9:$B$60,MATCH(B40,'Risk Register'!$M$9:$M$60,0)),"") -> Working capital runs out before the ramp pays back: Medium peak cash need $96K in Month 12 against $39K opening capital, funding gap $116K needed by Month 2; Low peak $114K in Month 24 | J40: =IFERROR(INDEX('Risk Register'!$I$9:$I$60,MATCH(B40,'Risk Register'!$M$9:$M$60,0)),"") -> Lucy, Mark
A41: Rank 2 | B41: 2 | C41: =IFERROR(INDEX('Risk Register'!$A$9:$A$60,MATCH(B41,'Risk Register'!$M$9:$M$60,0)),"") -> R03 | D41: =IFERROR(INDEX('Risk Register'!$F$9:$F$60,MATCH(B41,'Risk Register'!$M$9:$M$60,0)),"") -> 15 | E41: =IFERROR(INDEX('Risk Register'!$D$9:$D$60,MATCH(B41,'Risk Register'!$M$9:$M$60,0)),"") -> 3 | F41: =IFERROR(INDEX('Risk Register'!$E$9:$E$60,MATCH(B41,'Risk Register'!$M$9:$M$60,0)),"") -> 5 | G41: =IFERROR(INDEX('Risk Register'!$K$9:$K$60,MATCH(B41,'Risk Register'!$M$9:$M$60,0)),"") -> Yes | I41: =IFERROR(INDEX('Risk Register'!$B$9:$B$60,MATCH(B41,'Risk Register'!$M$9:$M$60,0)),"") -> Factory cost gap: the Alibaba benchmark for a comparable 30 ft AOC is $17 to $22 FOB against the H2 base of $7.38 FOB for the hero; at the benchmark the hero loses ($1.61) to ($8.61) per unit at $44.99 and Medium 18 month net turns to ($287K) | J41: =IFERROR(INDEX('Risk Register'!$I$9:$I$60,MATCH(B41,'Risk Register'!$M$9:$M$60,0)),"") -> Lucy
A42: Rank 3 | B42: 3 | C42: =IFERROR(INDEX('Risk Register'!$A$9:$A$60,MATCH(B42,'Risk Register'!$M$9:$M$60,0)),"") -> R01 | D42: =IFERROR(INDEX('Risk Register'!$F$9:$F$60,MATCH(B42,'Risk Register'!$M$9:$M$60,0)),"") -> 12 | E42: =IFERROR(INDEX('Risk Register'!$D$9:$D$60,MATCH(B42,'Risk Register'!$M$9:$M$60,0)),"") -> 4 | F42: =IFERROR(INDEX('Risk Register'!$E$9:$E$60,MATCH(B42,'Risk Register'!$M$9:$M$60,0)),"") -> 3 | G42: =IFERROR(INDEX('Risk Register'!$K$9:$K$60,MATCH(B42,'Risk Register'!$M$9:$M$60,0)),"") -> No | I42: =IFERROR(INDEX('Risk Register'!$B$9:$B$60,MATCH(B42,'Risk Register'!$M$9:$M$60,0)),"") -> Pending second Section 301 action adds 10 points of duty on China origin goods (stress case 50.1% against the copper base 40.1%) | J42: =IFERROR(INDEX('Risk Register'!$I$9:$I$60,MATCH(B42,'Risk Register'!$M$9:$M$60,0)),"") -> Broker, Mark
A43: Rank 4 | B43: 4 | C43: =IFERROR(INDEX('Risk Register'!$A$9:$A$60,MATCH(B43,'Risk Register'!$M$9:$M$60,0)),"") -> R14 | D43: =IFERROR(INDEX('Risk Register'!$F$9:$F$60,MATCH(B43,'Risk Register'!$M$9:$M$60,0)),"") -> 12 | E43: =IFERROR(INDEX('Risk Register'!$D$9:$D$60,MATCH(B43,'Risk Register'!$M$9:$M$60,0)),"") -> 3 | F43: =IFERROR(INDEX('Risk Register'!$E$9:$E$60,MATCH(B43,'Risk Register'!$M$9:$M$60,0)),"") -> 4 | G43: =IFERROR(INDEX('Risk Register'!$K$9:$K$60,MATCH(B43,'Risk Register'!$M$9:$M$60,0)),"") -> No | I43: =IFERROR(INDEX('Risk Register'!$B$9:$B$60,MATCH(B43,'Risk Register'!$M$9:$M$60,0)),"") -> Korea filings: the overseas direct investment report (ODI) is not accepted by the foreign exchange bank before capital moves, or the remittance, securities acquisition and annual business performance reports are missed; enforcement against individual online sellers is rising | J43: =IFERROR(INDEX('Risk Register'!$I$9:$I$60,MATCH(B43,'Risk Register'!$M$9:$M$60,0)),"") -> Lucy, 세무사
A44: Rank 5 | B44: 5 | C44: =IFERROR(INDEX('Risk Register'!$A$9:$A$60,MATCH(B44,'Risk Register'!$M$9:$M$60,0)),"") -> R19 | D44: =IFERROR(INDEX('Risk Register'!$F$9:$F$60,MATCH(B44,'Risk Register'!$M$9:$M$60,0)),"") -> 12 | E44: =IFERROR(INDEX('Risk Register'!$D$9:$D$60,MATCH(B44,'Risk Register'!$M$9:$M$60,0)),"") -> 3 | F44: =IFERROR(INDEX('Risk Register'!$E$9:$E$60,MATCH(B44,'Risk Register'!$M$9:$M$60,0)),"") -> 4 | G44: =IFERROR(INDEX('Risk Register'!$K$9:$K$60,MATCH(B44,'Risk Register'!$M$9:$M$60,0)),"") -> Yes | I44: =IFERROR(INDEX('Risk Register'!$B$9:$B$60,MATCH(B44,'Risk Register'!$M$9:$M$60,0)),"") -> Demand shortfall: conversion below plan so units track the Low case (60% of Medium); Low 18 month revenue $633K and net ($20K), Month 12 revenue $46,740 against the $50,000 kill line and $86,100 in Medium | J44: =IFERROR(INDEX('Risk Register'!$I$9:$I$60,MATCH(B44,'Risk Register'!$M$9:$M$60,0)),"") -> Mark
A45: Rank 6 | B45: 6 | C45: =IFERROR(INDEX('Risk Register'!$A$9:$A$60,MATCH(B45,'Risk Register'!$M$9:$M$60,0)),"") -> R20 | D45: =IFERROR(INDEX('Risk Register'!$F$9:$F$60,MATCH(B45,'Risk Register'!$M$9:$M$60,0)),"") -> 12 | E45: =IFERROR(INDEX('Risk Register'!$D$9:$D$60,MATCH(B45,'Risk Register'!$M$9:$M$60,0)),"") -> 4 | F45: =IFERROR(INDEX('Risk Register'!$E$9:$E$60,MATCH(B45,'Risk Register'!$M$9:$M$60,0)),"") -> 3 | G45: =IFERROR(INDEX('Risk Register'!$K$9:$K$60,MATCH(B45,'Risk Register'!$M$9:$M$60,0)),"") -> No | I45: =IFERROR(INDEX('Risk Register'!$B$9:$B$60,MATCH(B45,'Risk Register'!$M$9:$M$60,0)),"") -> Competition and price compression: $8 copper cables anchor the category and other AOC brands cut price; ASP minus 10% takes Medium 18 month net to $120K and the model already compresses ASP 2% per year | J45: =IFERROR(INDEX('Risk Register'!$I$9:$I$60,MATCH(B45,'Risk Register'!$M$9:$M$60,0)),"") -> Mark, Lucy
...
